<?xml version="1.0" ?>
<!-- Generated using onshape-to-robot -->
<!-- Onshape https://cad.onshape.com/documents/e95d3c063e2b7f45272d3fcb/w/c59c777708add0ad5bdf1ca3/e/2eea157a8505fef62e822018 -->
<mujoco model="mjcf">
  <compiler angle="radian" meshdir="../assets" autolimits="true"/>
  <default>
    <default class="mjcf">
      <joint frictionloss="0.1" armature="0.005"/>
      <position kp="50" dampratio="1"/>
      <default class="visual">
        <geom type="mesh" contype="0" conaffinity="0" group="2"/>
      </default>
      <default class="collision">
        <geom group="3"/>
      </default>
    </default>
  </default>
  <worldbody>
    <!-- Link body_base_link -->
    <body name="body_base_link" pos="0 0 0" quat="1 0 0 0" childclass="mjcf">
      <freejoint name="body_base_link_freejoint"/>
      <inertial pos="-4.20726e-05 -9.03729e-06 0.422113" mass="76.8996" fullinertia="8.30255 7.32437 2.45005 -0.000118077 -0.000419172 -0.000193969"/>
      <!-- Part body_base_link_parts -->
      <geom type="mesh" class="visual" pos="-4.20726e-05 -9.03729e-06 0.422113" quat="1 0 0 0" mesh="body_base_link_visual" material="body_base_link_visual_material"/>
      <geom type="mesh" class="collision" pos="-4.20726e-05 -9.03729e-06 0.422113" quat="1 0 0 0" mesh="body_base_link_collision" material="body_base_link_collision_material"/>
      <!-- Link waist_yaw_link -->
      <body name="waist_yaw_link" pos="-2.29257e-05 -5.21767e-07 1.08679" quat="0.707107 5.66021e-14 -1.58651e-13 0.707107">
        <!-- Joint from body_base_link to waist_yaw_link -->
        <joint axis="0 0 1" name="waist_yaw_joint" type="hinge" range="-3.1415926535898127 3.1415926535897736" armature="0.94096" damping="1.5"/>
        <inertial pos="6.96649e-09 0.0176858 0.0185467" mass="0.318626" fullinertia="0.000368773 0.000823063 0.0010301 -9.75394e-11 1.12765e-11 -7.3433e-05"/>
        <!-- Part waist_yaw_link_parts -->
        <geom type="mesh" class="visual" pos="6.96649e-09 0.0176858 0.0185467" quat="0.707107 -5.66018e-14 1.58318e-13 -0.707107" mesh="waist_yaw_link_visual" material="waist_yaw_link_visual_material"/>
        <geom type="mesh" class="collision" pos="6.96649e-09 0.0176858 0.0185467" quat="0.707107 -5.66018e-14 1.58318e-13 -0.707107" mesh="waist_yaw_link_collision" material="waist_yaw_link_collision_material"/>
        <!-- Frame closing_waist_left_passive2_joint_1 -->
        <site group="3" name="closing_waist_left_passive2_joint_1" pos="0.088 0.05 0.035" quat="4.2981e-14 8.4942e-14 -0.707107 0.707107"/>
        <!-- Frame closing_waist_right_passive2_joint_1 -->
        <site group="3" name="closing_waist_right_passive2_joint_1" pos="-0.088 0.05 0.035" quat="2.21002e-14 6.41383e-14 -0.707107 0.707107"/>
        <!-- Link waist_roll_link -->
        <body name="waist_roll_link" pos="-1.61684e-14 0.018 0.035" quat="0.707107 0.707107 -2.85327e-14 -6.97906e-14">
          <!-- Joint from waist_yaw_link to waist_roll_link -->
          <joint axis="0 0 1" name="waist_roll_passive_joint" type="hinge" range="-0.1745329251994384 0.1745329251994275"/>
          <inertial pos="-5.81324e-13 -1.64791e-16 0.0177" mass="0.125178" fullinertia="1.24231e-05 2.84421e-05 2.01802e-05 9.2054e-19 -2.72412e-16 9.3826e-19"/>
          <!-- Part waist_roll_link_parts -->
          <geom type="mesh" class="visual" pos="-5.81324e-13 0 0.0177" quat="0.5 -0.5 -0.5 -0.5" mesh="waist_roll_link_visual" material="waist_roll_link_visual_material"/>
          <geom type="mesh" class="collision" pos="-5.81324e-13 0 0.0177" quat="0.5 -0.5 -0.5 -0.5" mesh="waist_roll_link_collision" material="waist_roll_link_collision_material"/>
          <!-- Link chest_link -->
          <body name="chest_link" pos="-0.023 3.10862e-15 0.0177" quat="0.707107 -1.26301e-14 0.707107 -1.07475e-14">
            <!-- Joint from waist_roll_link to chest_link -->
            <joint axis="0 0 1" name="waist_pitch_passive_joint" type="hinge" range="-0.3490658503988364 0.5235987755983282"/>
            <inertial pos="0.00598813 0.153501 0.0231031" mass="8.27946" fullinertia="0.119436 0.0529458 0.0772233 -0.00499883 4.07256e-05 -2.85322e-05"/>
            <!-- Part chest_link_parts -->
            <geom type="mesh" class="visual" pos="0.00598813 0.153501 0.0231031" quat="1.11705e-13 2.39721e-14 -0.707107 -0.707107" mesh="chest_link_visual" material="chest_link_visual_material"/>
            <geom type="mesh" class="collision" pos="0.00598813 0.153501 0.0231031" quat="1.11705e-13 2.39721e-14 -0.707107 -0.707107" mesh="chest_link_collision" material="chest_link_collision_material"/>
            <!-- Link waist_left_link -->
            <body name="waist_left_link" pos="8.59392e-12 0.07 0.1105" quat="2.90382e-14 0.707107 -0.707107 1.68577e-14">
              <!-- Joint from chest_link to waist_left_link -->
              <joint axis="0 0 1" name="waist_left_joint" type="hinge" range="-0.6108780951764704 1.0471846942181424" armature="0.94096" damping="1.5"/>
              <inertial pos="2.84367e-07 -0.0221506 -0.0066566" mass="0.0904052" fullinertia="8.85019e-05 3.64587e-05 0.000109689 6.68215e-10 1.74121e-10 -1.35386e-05"/>
              <!-- Part waist_left_link_parts -->
              <geom type="mesh" class="visual" pos="2.84367e-07 -0.0221506 -0.0066566" quat="0.5 -0.5 -0.5 0.5" mesh="waist_left_link_visual" material="waist_left_link_visual_material"/>
              <geom type="mesh" class="collision" pos="2.84367e-07 -0.0221506 -0.0066566" quat="0.5 -0.5 -0.5 0.5" mesh="waist_left_link_collision" material="waist_left_link_collision_material"/>
              <!-- Link waist_left_passive_link -->
              <body name="waist_left_passive_link" pos="6.42849e-07 -0.05 -0.0205" quat="0.499997 0.500003 -0.499997 0.500003">
                <!-- Joint from waist_left_link to waist_left_passive_link -->
                <joint axis="0 0 1" name="waist_left_passive1_joint" type="ball"/>
                <inertial pos="0.00782784 -0.0357958 -0.000151758" mass="0.029442" fullinertia="2.28696e-05 3.44733e-06 2.4643e-05 6.4948e-06 2.77059e-08 -9.07758e-08"/>
                <!-- Part waist_left_passive_link_parts -->
                <geom type="mesh" class="visual" pos="0.00782784 -0.0357958 -0.000151758" quat="0.499997 -0.500003 0.500003 0.499997" mesh="waist_left_passive_link_visual" material="waist_left_passive_link_visual_material"/>
                <geom type="mesh" class="collision" pos="0.00782784 -0.0357958 -0.000151758" quat="0.499997 -0.500003 0.500003 0.499997" mesh="waist_left_passive_link_collision" material="waist_left_passive_link_collision_material"/>
                <!-- Frame closing_waist_left_passive2_joint_2 -->
                <site group="3" name="closing_waist_left_passive2_joint_2" pos="0.02 -0.0699994 -0.0002991" quat="0.00206636 -0.999998 -5.23666e-07 0.000245262"/>
              </body>
            </body>
            <!-- Link waist_right_link -->
            <body name="waist_right_link" pos="-8.58013e-12 0.07 -0.0645" quat="0.707107 -2.92654e-14 -1.69864e-14 -0.707107">
              <!-- Joint from chest_link to waist_right_link -->
              <joint axis="0 0 1" name="waist_right_joint" type="hinge" range="-1.047184694220563 0.61087809517405" armature="0.94096" damping="1.5"/>
              <inertial pos="2.85212e-07 0.0221506 -0.0066566" mass="0.0904052" fullinertia="8.85019e-05 3.64587e-05 0.000109689 -6.70022e-10 1.7401e-10 1.35386e-05"/>
              <!-- Part waist_right_link_parts -->
              <geom type="mesh" class="visual" pos="2.85212e-07 0.0221506 -0.0066566" quat="0.5 0.5 -0.5 -0.5" mesh="waist_right_link_visual" material="waist_right_link_visual_material"/>
              <geom type="mesh" class="collision" pos="2.85212e-07 0.0221506 -0.0066566" quat="0.5 0.5 -0.5 -0.5" mesh="waist_right_link_collision" material="waist_right_link_collision_material"/>
              <!-- Link waist_right_passive_link -->
              <body name="waist_right_passive_link" pos="6.42849e-07 0.05 -0.0205" quat="0.500003 -0.499997 0.500003 0.499997">
                <!-- Joint from waist_right_link to waist_right_passive_link -->
                <joint axis="0 0 1" name="waist_right_passive1_joint" type="ball"/>
                <inertial pos="-0.00782784 -0.0357958 -0.000148717" mass="0.029442" fullinertia="2.28696e-05 3.44734e-06 2.4643e-05 -6.4948e-06 -2.76119e-08 -9.13537e-08"/>
                <!-- Part waist_right_passive_link_parts -->
                <geom type="mesh" class="visual" pos="-0.00782784 -0.0357958 -0.000148717" quat="0.499997 -0.500003 0.500003 0.499997" mesh="waist_right_passive_link_visual" material="waist_right_passive_link_visual_material"/>
                <geom type="mesh" class="collision" pos="-0.00782784 -0.0357958 -0.000148717" quat="0.499997 -0.500003 0.500003 0.499997" mesh="waist_right_passive_link_collision" material="waist_right_passive_link_collision_material"/>
                <!-- Frame closing_waist_right_passive2_joint_2 -->
                <site group="3" name="closing_waist_right_passive2_joint_2" pos="-0.02 -0.0699994 -0.0002991" quat="0.0018833 -0.999998 1.8925e-06 -0.000885968"/>
              </body>
            </body>
            <!-- Link left_shoulder_pitch_link -->
            <body name="left_shoulder_pitch_link" pos="0.01443 0.247814 0.160316" quat="0.996195 -0.0871557 2.77556e-15 -3.08012e-16">
              <!-- Joint from chest_link to left_shoulder_pitch_link -->
              <joint axis="0 0 1" name="left_shoulder_pitch_joint" type="hinge" range="-2.356194490192352 2.3561944901923377" armature="0.70637" damping="1.5"/>
              <inertial pos="0.00445247 -0.00401905 0.0555302" mass="1.61013" fullinertia="0.00169156 0.00169393 0.00136864 -6.04835e-05 -1.91261e-05 3.84532e-05"/>
              <!-- Part left_shoulder_pitch_link_parts -->
              <geom type="mesh" class="visual" pos="0.00445247 -0.00401905 0.0555302" quat="1.07258e-13 3.61288e-14 -0.642788 -0.766044" mesh="left_shoulder_pitch_link_visual" material="left_shoulder_pitch_link_visual_material"/>
              <geom type="mesh" class="collision" pos="0.00445247 -0.00401905 0.0555302" quat="1.07258e-13 3.61288e-14 -0.642788 -0.766044" mesh="left_shoulder_pitch_link_collision" material="left_shoulder_pitch_link_collision_material"/>
              <!-- Link left_shoulder_roll_link -->
              <body name="left_shoulder_roll_link" pos="0.0311127 -0.0311127 0.06" quat="0.701057 0.560986 0.430459 0.092296">
                <!-- Joint from left_shoulder_pitch_link to left_shoulder_roll_link -->
                <joint axis="0 0 1" name="left_shoulder_roll_joint" type="hinge" range="-1.0471975511971885 1.047197551196007" armature="0.70637" damping="1.5"/>
                <inertial pos="-0.113042 1.86932e-05 -0.0428809" mass="1.23133" fullinertia="0.0010626 0.00194814 0.00180368 -4.20698e-07 -5.54234e-06 1.63617e-07"/>
                <!-- Part left_shoulder_roll_link_parts -->
                <geom type="mesh" class="visual" pos="-0.113042 1.86932e-05 -0.0428809" quat="0.347397 -0.270424 0.880371 0.176447" mesh="left_shoulder_roll_link_visual" material="left_shoulder_roll_link_visual_material"/>
                <geom type="mesh" class="collision" pos="-0.113042 1.86932e-05 -0.0428809" quat="0.347397 -0.270424 0.880371 0.176447" mesh="left_shoulder_roll_link_collision" material="left_shoulder_roll_link_collision_material"/>
                <!-- Link left_shoulder_yaw_link -->
                <body name="left_shoulder_yaw_link" pos="-0.16 -8.10463e-14 -0.043" quat="0.5 0.5 -0.5 -0.5">
                  <!-- Joint from left_shoulder_roll_link to left_shoulder_yaw_link -->
                  <joint axis="0 0 1" name="left_shoulder_yaw_joint" type="hinge" range="-1.5707963267949232 1.57079632679487" armature="0.12749" damping="1.5"/>
                  <inertial pos="0.00144727 0.00119292 0.0961527" mass="1.32768" fullinertia="0.00221382 0.00222585 0.000940724 4.50044e-07 -2.45225e-05 5.42601e-05"/>
                  <!-- Part left_shoulder_yaw_link_parts -->
                  <geom type="mesh" class="visual" pos="0.00144727 0.00119292 0.0961527" quat="0.489922 0.660873 -0.566895 0.0430516" mesh="left_shoulder_yaw_link_visual" material="left_shoulder_yaw_link_visual_material"/>
                  <geom type="mesh" class="collision" pos="0.00144727 0.00119292 0.0961527" quat="0.489922 0.660873 -0.566895 0.0430516" mesh="left_shoulder_yaw_link_collision" material="left_shoulder_yaw_link_collision_material"/>
                  <!-- Link left_elbow_pitch_link -->
                  <body name="left_elbow_pitch_link" pos="0.0405 -2.60902e-14 0.11" quat="0.587938 0.392847 0.587938 0.392847">
                    <!-- Joint from left_shoulder_yaw_link to left_elbow_pitch_link -->
                    <joint axis="0 0 1" name="left_elbow_pitch_joint" type="hinge" range="-1.1780972450965326 1.1780972450958123" armature="0.12749" damping="1.5"/>
                    <inertial pos="-0.0818905 0.000647018 -0.0402032" mass="1.17763" fullinertia="0.00094916 0.00125269 0.00115385 -1.58858e-05 -3.04234e-05 7.52023e-08"/>
                    <!-- Part left_elbow_pitch_link_parts -->
                    <geom type="mesh" class="visual" pos="-0.0818905 0.000647018 -0.0402032" quat="0.23128 -0.0519277 -0.864052 0.444102" mesh="left_elbow_pitch_link_visual" material="left_elbow_pitch_link_visual_material"/>
                    <geom type="mesh" class="collision" pos="-0.0818905 0.000647018 -0.0402032" quat="0.23128 -0.0519277 -0.864052 0.444102" mesh="left_elbow_pitch_link_collision" material="left_elbow_pitch_link_collision_material"/>
                    <!-- Link left_wrist_roll_link -->
                    <body name="left_wrist_roll_link" pos="-0.124 -2.85327e-14 -0.0405" quat="0.5 0.5 -0.5 -0.5">
                      <!-- Joint from left_elbow_pitch_link to left_wrist_roll_link -->
                      <joint axis="0 0 1" name="left_wrist_roll_joint" type="hinge" range="-1.5707963267943397 1.5707963267954534" armature="0.12749" damping="1.5"/>
                      <inertial pos="-7.42693e-11 0.000278379 0.0385646" mass="0.404705" fullinertia="0.000421826 0.00034236 0.000208792 -6.65218e-12 -1.68616e-12 1.62664e-05"/>
                      <!-- Part left_wrist_roll_link_parts -->
                      <geom type="mesh" class="visual" pos="-7.42691e-11 0.000278379 0.0385646" quat="0.299651 0.512473 -0.120299 0.795681" mesh="left_wrist_roll_link_visual" material="left_wrist_roll_link_visual_material"/>
                      <geom type="mesh" class="collision" pos="-7.42691e-11 0.000278379 0.0385646" quat="0.299651 0.512473 -0.120299 0.795681" mesh="left_wrist_roll_link_collision" material="left_wrist_roll_link_collision_material"/>
                      <!-- Link left_wrist_pitch_link -->
                      <body name="left_wrist_pitch_link" pos="-5.44009e-15 -0.022 0.099" quat="1.6738e-13 -2.03769e-13 0.707107 0.707107">
                        <!-- Joint from left_wrist_roll_link to left_wrist_pitch_link -->
                        <joint axis="0 0 1" name="left_wrist_pitch_joint" type="hinge" range="-0.7853981633974554 0.7853981633974412" armature="0.3" damping="1.5"/>
                        <inertial pos="-0.00106391 -2.33324e-11 0.0219286" mass="0.304398" fullinertia="8.08739e-05 0.000118571 0.000107519 1.64597e-11 5.38408e-07 4.41999e-12"/>
                        <!-- Part left_wrist_pitch_link_parts -->
                        <geom type="mesh" class="visual" pos="-0.00106391 -2.33324e-11 0.0219286" quat="0.477567 -0.647696 -0.574259 0.150488" mesh="left_wrist_pitch_link_visual" material="left_wrist_pitch_link_visual_material"/>
                        <geom type="mesh" class="collision" pos="-0.00106391 -2.33324e-11 0.0219286" quat="0.477567 -0.647696 -0.574259 0.150488" mesh="left_wrist_pitch_link_collision" material="left_wrist_pitch_link_collision_material"/>
                        <!-- Link left_wrist_yaw_link -->
                        <body name="left_wrist_yaw_link" pos="-0.03155 2.88658e-15 0.022" quat="0.707107 -1.17207e-13 0.707107 -1.11418e-13">
                          <!-- Joint from left_wrist_pitch_link to left_wrist_yaw_link -->
                          <joint axis="0 0 1" name="left_wrist_yaw_joint" type="hinge" range="-0.7853981633971223 1.5707963267952225" armature="0.3" damping="1.5"/>
                          <inertial pos="-1.12308e-10 0.0267049 0.0302175" mass="0.0547065" fullinertia="5.07331e-05 4.43376e-05 2.14007e-05 3.12122e-13 -2.86228e-11 2.44558e-07"/>
                          <!-- Part left_wrist_yaw_link_parts -->
                          <geom type="mesh" class="visual" pos="-1.12308e-10 0.0267049 0.0302175" quat="0.0683713 0.564401 0.743753 0.351579" mesh="left_wrist_yaw_link_visual" material="left_wrist_yaw_link_visual_material"/>
                          <geom type="mesh" class="collision" pos="-1.12308e-10 0.0267049 0.0302175" quat="0.0683713 0.564401 0.743753 0.351579" mesh="left_wrist_yaw_link_collision" material="left_wrist_yaw_link_collision_material"/>
                          <!-- Frame left_hand -->
                          <site group="3" name="left_hand" pos="-2.07612e-14 0.0485 0.03005" quat="4.10783e-15 -5.72223e-15 0.707107 0.707107"/>
                        </body>
                      </body>
                    </body>
                  </body>
                </body>
              </body>
            </body>
            <!-- Link right_shoulder_pitch_link -->
            <body name="right_shoulder_pitch_link" pos="0.01443 0.247814 -0.114316" quat="2.5912e-14 -1.62171e-14 -0.996195 -0.0871557">
              <!-- Joint from chest_link to right_shoulder_pitch_link -->
              <joint axis="0 0 1" name="right_shoulder_pitch_joint" type="hinge" range="-2.356194490192399 2.3561944901922907" armature="0.70637" damping="1.5"/>
              <inertial pos="-0.00435028 -0.00412125 0.0556137" mass="1.61012" fullinertia="0.00169967 0.00168831 0.00136875 6.05419e-05 2.11785e-05 4.20073e-05"/>
              <!-- Part right_shoulder_pitch_link_parts -->
              <geom type="mesh" class="visual" pos="-0.00435028 -0.00412125 0.0556137" quat="0.766044 -0.642788 1.0647e-13 -4.39387e-14" mesh="right_shoulder_pitch_link_visual" material="right_shoulder_pitch_link_visual_material"/>
              <geom type="mesh" class="collision" pos="-0.00435028 -0.00412125 0.0556137" quat="0.766044 -0.642788 1.0647e-13 -4.39387e-14" mesh="right_shoulder_pitch_link_collision" material="right_shoulder_pitch_link_collision_material"/>
              <!-- Link right_shoulder_roll_link -->
              <body name="right_shoulder_roll_link" pos="-0.0311127 -0.0311127 0.06" quat="0.092296 -0.430459 -0.560986 0.701057">
                <!-- Joint from right_shoulder_pitch_link to right_shoulder_roll_link -->
                <joint axis="0 0 1" name="right_shoulder_roll_joint" type="hinge" range="-1.0471975511962044 1.0471975511969909" armature="0.70637" damping="1.5"/>
                <inertial pos="-0.113042 -1.86911e-05 -0.0428187" mass="1.23133" fullinertia="0.00106257 0.00194811 0.00180368 4.20577e-07 -7.26269e-06 1.56805e-07"/>
                <!-- Part right_shoulder_roll_link_parts -->
                <geom type="mesh" class="visual" pos="-0.113042 -1.86911e-05 -0.0428187" quat="0.347397 0.270424 0.880371 -0.176447" mesh="right_shoulder_roll_link_visual" material="right_shoulder_roll_link_visual_material"/>
                <geom type="mesh" class="collision" pos="-0.113042 -1.86911e-05 -0.0428187" quat="0.347397 0.270424 0.880371 -0.176447" mesh="right_shoulder_roll_link_collision" material="right_shoulder_roll_link_collision_material"/>
                <!-- Link right_shoulder_yaw_link -->
                <body name="right_shoulder_yaw_link" pos="-0.16 3.39728e-14 -0.043" quat="0.5 0.5 -0.5 -0.5">
                  <!-- Joint from right_shoulder_roll_link to right_shoulder_yaw_link -->
                  <joint axis="0 0 1" name="right_shoulder_yaw_joint" type="hinge" range="-1.5707963267949383 1.5707963267948548" armature="0.12749" damping="1.5"/>
                  <inertial pos="-0.00144725 0.00119294 0.096095" mass="1.32768" fullinertia="0.0022117 0.00222373 0.000940725 -4.50574e-07 2.68485e-05 5.44907e-05"/>
                  <!-- Part right_shoulder_yaw_link_parts -->
                  <geom type="mesh" class="visual" pos="-0.00144725 0.00119294 0.096095" quat="0.0430516 0.566895 -0.660873 0.489922" mesh="right_shoulder_yaw_link_visual" material="right_shoulder_yaw_link_visual_material"/>
                  <geom type="mesh" class="collision" pos="-0.00144725 0.00119294 0.096095" quat="0.0430516 0.566895 -0.660873 0.489922" mesh="right_shoulder_yaw_link_collision" material="right_shoulder_yaw_link_collision_material"/>
                  <!-- Link right_elbow_pitch_link -->
                  <body name="right_elbow_pitch_link" pos="-0.0405 4.20775e-14 0.11" quat="0.392847 -0.587938 -0.392847 0.587938">
                    <!-- Joint from right_shoulder_yaw_link to right_elbow_pitch_link -->
                    <joint axis="0 0 1" name="right_elbow_pitch_joint" type="hinge" range="-1.1780972450967344 1.1780972450956104" armature="0.12749" damping="1.5"/>
                    <inertial pos="-0.0818905 -0.000712004 -0.0402032" mass="1.17763" fullinertia="0.000949056 0.00125269 0.00115375 1.79772e-05 -3.04229e-05 -4.18437e-07"/>
                    <!-- Part right_elbow_pitch_link_parts -->
                    <geom type="mesh" class="visual" pos="-0.0818905 -0.000712004 -0.0402032" quat="0.23128 0.0519277 -0.864052 -0.444102" mesh="right_elbow_pitch_link_visual" material="right_elbow_pitch_link_visual_material"/>
                    <geom type="mesh" class="collision" pos="-0.0818905 -0.000712004 -0.0402032" quat="0.23128 0.0519277 -0.864052 -0.444102" mesh="right_elbow_pitch_link_collision" material="right_elbow_pitch_link_collision_material"/>
                    <!-- Link right_wrist_roll_link -->
                    <body name="right_wrist_roll_link" pos="-0.124 -6.69464e-14 -0.0405" quat="0.5 -0.5 -0.5 0.5">
                      <!-- Joint from right_elbow_pitch_link to right_wrist_roll_link -->
                      <joint axis="0 0 1" name="right_wrist_roll_joint" type="hinge" range="-1.5707963267949197 1.5707963267948735" armature="0.12749" damping="1.5"/>
                      <inertial pos="1.97018e-10 -0.000317914 0.0385646" mass="0.404705" fullinertia="0.000420807 0.00034236 0.000207773 -5.82532e-12 1.70915e-12 -1.57794e-05"/>
                      <!-- Part right_wrist_roll_link_parts -->
                      <geom type="mesh" class="visual" pos="1.97018e-10 -0.000317914 0.0385646" quat="0.299651 -0.512473 -0.120299 -0.795681" mesh="right_wrist_roll_link_visual" material="right_wrist_roll_link_visual_material"/>
                      <geom type="mesh" class="collision" pos="1.97018e-10 -0.000317914 0.0385646" quat="0.299651 -0.512473 -0.120299 -0.795681" mesh="right_wrist_roll_link_collision" material="right_wrist_roll_link_collision_material"/>
                      <!-- Link right_wrist_ptich_link -->
                      <body name="right_wrist_ptich_link" pos="-1.22125e-15 0.022 0.099" quat="0.707107 0.707107 6.77236e-15 -7.48197e-15">
                        <!-- Joint from right_wrist_roll_link to right_wrist_ptich_link -->
                        <joint axis="0 0 1" name="right_wrist_pitch_joint" type="hinge" range="-0.7853981633974678 0.7853981633974287" armature="0.3" damping="1.5"/>
                        <inertial pos="-0.00106391 -1.95311e-10 0.0220599" mass="0.304398" fullinertia="8.08744e-05 0.000118571 0.000107519 3.53192e-13 -5.34681e-07 -9.46581e-11"/>
                        <!-- Part right_wrist_ptich_link_parts -->
                        <geom type="mesh" class="visual" pos="-0.00106391 -1.95311e-10 0.0220599" quat="0.150488 0.574259 0.647696 0.477567" mesh="right_wrist_ptich_link_visual" material="right_wrist_ptich_link_visual_material"/>
                        <geom type="mesh" class="collision" pos="-0.00106391 -1.95311e-10 0.0220599" quat="0.150488 0.574259 0.647696 0.477567" mesh="right_wrist_ptich_link_collision" material="right_wrist_ptich_link_collision_material"/>
                        <!-- Link right_wrist_yaw_link -->
                        <body name="right_wrist_yaw_link" pos="-0.03155 2.08722e-14 0.022" quat="0.707107 5.20535e-13 0.707107 1.48454e-13">
                          <!-- Joint from right_wrist_ptich_link to right_wrist_yaw_link -->
                          <joint axis="0 0 1" name="right_wrist_yaw_joint" type="hinge" range="-0.7853981633973852 1.5707963267949596" armature="0.3" damping="1.5"/>
                          <inertial pos="-1.12277e-10 0.0267049 0.0302175" mass="0.0547065" fullinertia="5.07331e-05 4.43376e-05 2.14007e-05 3.12103e-13 -2.86228e-11 2.44558e-07"/>
                          <!-- Part right_wrist_yaw_link_parts -->
                          <geom type="mesh" class="visual" pos="-1.12277e-10 0.0267049 0.0302175" quat="0.564401 0.0683713 0.351579 0.743753" mesh="right_wrist_yaw_link_visual" material="right_wrist_yaw_link_visual_material"/>
                          <geom type="mesh" class="collision" pos="-1.12277e-10 0.0267049 0.0302175" quat="0.564401 0.0683713 0.351579 0.743753" mesh="right_wrist_yaw_link_collision" material="right_wrist_yaw_link_collision_material"/>
                          <!-- Frame right_hand -->
                          <site group="3" name="right_hand" pos="3.475e-14 0.0485 0.03005" quat="2.10942e-15 -2.17405e-14 -0.707107 -0.707107"/>
                        </body>
                      </body>
                    </body>
                  </body>
                </body>
              </body>
            </body>
            <!-- Link neck_yaw_link -->
            <body name="neck_yaw_link" pos="0.01443 0.35455 0.023" quat="2.81105e-14 2.25872e-14 0.707107 -0.707107">
              <!-- Joint from chest_link to neck_yaw_link -->
              <joint axis="0 0 1" name="neck_yaw_joint" type="hinge" range="-3.1415926535897487 3.1415926535898375" armature="0.3" damping="1.5"/>
              <inertial pos="3.01692e-05 -2.95874e-08 -0.025262" mass="9.23497e-05" fullinertia="2.57971e-08 3.72339e-08 3.71365e-08 3.86016e-14 1.93175e-10 5.77657e-14"/>
              <!-- Part neck_yaw_link_parts -->
              <geom type="mesh" class="visual" pos="3.01692e-05 -2.95874e-08 -0.025262" quat="1.63214e-13 1 -9.78881e-14 9.20295e-14" mesh="neck_yaw_link_visual" material="neck_yaw_link_visual_material"/>
              <geom type="mesh" class="collision" pos="3.01692e-05 -2.95874e-08 -0.025262" quat="1.63214e-13 1 -9.78881e-14 9.20295e-14" mesh="neck_yaw_link_collision" material="neck_yaw_link_collision_material"/>
              <!-- Link neck_roll_link -->
              <body name="neck_roll_link" pos="-0.0303 2.17579e-15 -0.0255" quat="3.97223e-15 0.707107 3.88578e-15 0.707107">
                <!-- Joint from neck_yaw_link to neck_roll_link -->
                <joint axis="0 0 1" name="neck_roll_joint" type="hinge" range="-0.7853981633974394 0.7853981633974572" armature="0.3" damping="1.5"/>
                <inertial pos="-0.0430653 -0.000214234 0.0303228" mass="0.000107143" fullinertia="5.21547e-08 5.03411e-08 5.2811e-08 -2.41301e-10 4.00021e-10 -6.60546e-13"/>
                <!-- Part neck_roll_link_parts -->
                <geom type="mesh" class="visual" pos="-0.0430653 -0.000214234 0.0303228" quat="0.707107 -1.80655e-13 -0.707107 -4.23767e-14" mesh="neck_roll_link_visual" material="neck_roll_link_visual_material"/>
                <geom type="mesh" class="collision" pos="-0.0430653 -0.000214234 0.0303228" quat="0.707107 -1.80655e-13 -0.707107 -4.23767e-14" mesh="neck_roll_link_collision" material="neck_roll_link_collision_material"/>
                <!-- Link neck_pitch_link -->
                <body name="neck_pitch_link" pos="-0.047 0.0288 0.0303" quat="0.707107 0.707107 6.66134e-16 8.9927e-16">
                  <!-- Joint from neck_roll_link to neck_pitch_link -->
                  <joint axis="0 0 1" name="neck_pitch_joint" type="hinge" range="-0.34906585039886145 0.08726646259972091" armature="0.3" damping="1.5"/>
                  <inertial pos="-0.0597711 0.0161645 0.0287467" mass="0.645759" fullinertia="0.00323048 0.00321103 0.00372135 -0.000419023 2.92028e-06 -2.89743e-07"/>
                  <!-- Part neck_pitch_link_parts -->
                  <geom type="mesh" class="visual" pos="-0.0597711 0.0161645 0.0287467" quat="0.5 -0.5 -0.5 0.5" mesh="neck_pitch_link_visual" material="neck_pitch_link_visual_material"/>
                  <geom type="mesh" class="collision" pos="-0.0597711 0.0161645 0.0287467" quat="0.5 -0.5 -0.5 0.5" mesh="neck_pitch_link_collision" material="neck_pitch_link_collision_material"/>
                </body>
              </body>
            </body>
          </body>
        </body>
      </body>
    </body>
  </worldbody>
  <asset>
    <mesh file="merged/left_wrist_pitch_link_collision.stl"/>
    <mesh file="merged/waist_yaw_link_collision.stl"/>
    <mesh file="merged/right_shoulder_yaw_link_collision.stl"/>
    <mesh file="merged/right_wrist_yaw_link_visual.stl"/>
    <mesh file="merged/left_wrist_roll_link_visual.stl"/>
    <mesh file="merged/neck_yaw_link_visual.stl"/>
    <mesh file="merged/right_shoulder_roll_link_collision.stl"/>
    <mesh file="merged/left_elbow_pitch_link_collision.stl"/>
    <mesh file="merged/chest_link_visual.stl"/>
    <mesh file="merged/left_shoulder_pitch_link_collision.stl"/>
    <mesh file="merged/right_wrist_yaw_link_collision.stl"/>
    <mesh file="merged/waist_right_passive_link_visual.stl"/>
    <mesh file="merged/waist_left_link_collision.stl"/>
    <mesh file="merged/right_wrist_ptich_link_collision.stl"/>
    <mesh file="merged/waist_left_passive_link_collision.stl"/>
    <mesh file="merged/waist_right_link_visual.stl"/>
    <mesh file="merged/left_shoulder_yaw_link_visual.stl"/>
    <mesh file="merged/waist_left_passive_link_visual.stl"/>
    <mesh file="merged/left_shoulder_pitch_link_visual.stl"/>
    <mesh file="merged/left_elbow_pitch_link_visual.stl"/>
    <mesh file="merged/left_shoulder_yaw_link_collision.stl"/>
    <mesh file="merged/right_shoulder_yaw_link_visual.stl"/>
    <mesh file="merged/right_wrist_ptich_link_visual.stl"/>
    <mesh file="merged/waist_yaw_link_visual.stl"/>
    <mesh file="merged/left_wrist_yaw_link_visual.stl"/>
    <mesh file="merged/left_wrist_pitch_link_visual.stl"/>
    <mesh file="merged/right_elbow_pitch_link_collision.stl"/>
    <mesh file="merged/waist_right_passive_link_collision.stl"/>
    <mesh file="merged/left_wrist_yaw_link_collision.stl"/>
    <mesh file="merged/neck_pitch_link_collision.stl"/>
    <mesh file="merged/right_shoulder_roll_link_visual.stl"/>
    <mesh file="merged/right_shoulder_pitch_link_visual.stl"/>
    <mesh file="merged/waist_left_link_visual.stl"/>
    <mesh file="merged/waist_roll_link_visual.stl"/>
    <mesh file="merged/neck_roll_link_visual.stl"/>
    <mesh file="merged/neck_roll_link_collision.stl"/>
    <mesh file="merged/left_shoulder_roll_link_visual.stl"/>
    <mesh file="merged/right_wrist_roll_link_visual.stl"/>
    <mesh file="merged/body_base_link_collision.stl"/>
    <mesh file="merged/right_shoulder_pitch_link_collision.stl"/>
    <mesh file="merged/neck_pitch_link_visual.stl"/>
    <mesh file="merged/waist_right_link_collision.stl"/>
    <mesh file="merged/body_base_link_visual.stl"/>
    <mesh file="merged/waist_roll_link_collision.stl"/>
    <mesh file="merged/chest_link_collision.stl"/>
    <mesh file="merged/left_wrist_roll_link_collision.stl"/>
    <mesh file="merged/right_elbow_pitch_link_visual.stl"/>
    <mesh file="merged/neck_yaw_link_collision.stl"/>
    <mesh file="merged/left_shoulder_roll_link_collision.stl"/>
    <mesh file="merged/right_wrist_roll_link_collision.stl"/>
    <material name="body_base_link_visual_material" rgba="0.623029 0.814339 0.929126 1"/>
    <material name="body_base_link_collision_material" rgba="0.623029 0.814339 0.929126 1"/>
    <material name="waist_yaw_link_visual_material" rgba="0.62997 0.641781 0.667579 1"/>
    <material name="waist_yaw_link_collision_material" rgba="0.62997 0.641781 0.667579 1"/>
    <material name="waist_roll_link_visual_material" rgba="0.81186 0.895376 0.942702 1"/>
    <material name="waist_roll_link_collision_material" rgba="0.81186 0.895376 0.942702 1"/>
    <material name="chest_link_visual_material" rgba="0.775413 0.837045 0.865614 1"/>
    <material name="chest_link_collision_material" rgba="0.775413 0.837045 0.865614 1"/>
    <material name="waist_left_link_visual_material" rgba="0.651753 0.797067 0.884255 1"/>
    <material name="waist_left_link_collision_material" rgba="0.651753 0.797067 0.884255 1"/>
    <material name="waist_left_passive_link_visual_material" rgba="0.410396 0.459373 0.566349 1"/>
    <material name="waist_left_passive_link_collision_material" rgba="0.410396 0.459373 0.566349 1"/>
    <material name="waist_right_link_visual_material" rgba="0.651753 0.797067 0.884255 1"/>
    <material name="waist_right_link_collision_material" rgba="0.651753 0.797067 0.884255 1"/>
    <material name="waist_right_passive_link_visual_material" rgba="0.410396 0.459373 0.566349 1"/>
    <material name="waist_right_passive_link_collision_material" rgba="0.410396 0.459373 0.566349 1"/>
    <material name="left_shoulder_pitch_link_visual_material" rgba="0.661727 0.814348 0.901578 1"/>
    <material name="left_shoulder_pitch_link_collision_material" rgba="0.661727 0.814348 0.901578 1"/>
    <material name="left_shoulder_roll_link_visual_material" rgba="0.495831 0.510254 0.526236 1"/>
    <material name="left_shoulder_roll_link_collision_material" rgba="0.495831 0.510254 0.526236 1"/>
    <material name="left_shoulder_yaw_link_visual_material" rgba="0.534608 0.588362 0.619697 1"/>
    <material name="left_shoulder_yaw_link_collision_material" rgba="0.534608 0.588362 0.619697 1"/>
    <material name="left_elbow_pitch_link_visual_material" rgba="0.540973 0.537254 0.515031 1"/>
    <material name="left_elbow_pitch_link_collision_material" rgba="0.540973 0.537254 0.515031 1"/>
    <material name="left_wrist_roll_link_visual_material" rgba="0.616041 0.753599 0.806876 1"/>
    <material name="left_wrist_roll_link_collision_material" rgba="0.616041 0.753599 0.806876 1"/>
    <material name="left_wrist_pitch_link_visual_material" rgba="0.637078 0.780124 0.849341 1"/>
    <material name="left_wrist_pitch_link_collision_material" rgba="0.637078 0.780124 0.849341 1"/>
    <material name="left_wrist_yaw_link_visual_material" rgba="0.594174 0.694485 0.754671 1"/>
    <material name="left_wrist_yaw_link_collision_material" rgba="0.594174 0.694485 0.754671 1"/>
    <material name="right_shoulder_pitch_link_visual_material" rgba="0.666158 0.787435 0.786963 1"/>
    <material name="right_shoulder_pitch_link_collision_material" rgba="0.666158 0.787435 0.786963 1"/>
    <material name="right_shoulder_roll_link_visual_material" rgba="0.524464 0.533979 0.539688 1"/>
    <material name="right_shoulder_roll_link_collision_material" rgba="0.524464 0.533979 0.539688 1"/>
    <material name="right_shoulder_yaw_link_visual_material" rgba="0.579661 0.60817 0.621792 1"/>
    <material name="right_shoulder_yaw_link_collision_material" rgba="0.579661 0.60817 0.621792 1"/>
    <material name="right_elbow_pitch_link_visual_material" rgba="0.588878 0.529825 0.457356 1"/>
    <material name="right_elbow_pitch_link_collision_material" rgba="0.588878 0.529825 0.457356 1"/>
    <material name="right_wrist_roll_link_visual_material" rgba="0.650084 0.792364 0.881286 1"/>
    <material name="right_wrist_roll_link_collision_material" rgba="0.650084 0.792364 0.881286 1"/>
    <material name="right_wrist_ptich_link_visual_material" rgba="0.698304 0.762657 0.745079 1"/>
    <material name="right_wrist_ptich_link_collision_material" rgba="0.698304 0.762657 0.745079 1"/>
    <material name="right_wrist_yaw_link_visual_material" rgba="0.594174 0.694485 0.754671 1"/>
    <material name="right_wrist_yaw_link_collision_material" rgba="0.594174 0.694485 0.754671 1"/>
    <material name="neck_yaw_link_visual_material" rgba="0.470469 0.628627 0.781159 1"/>
    <material name="neck_yaw_link_collision_material" rgba="0.470469 0.628627 0.781159 1"/>
    <material name="neck_roll_link_visual_material" rgba="0.604479 0.726595 0.787909 1"/>
    <material name="neck_roll_link_collision_material" rgba="0.604479 0.726595 0.787909 1"/>
    <material name="neck_pitch_link_visual_material" rgba="0.649683 0.685003 0.686591 1"/>
    <material name="neck_pitch_link_collision_material" rgba="0.649683 0.685003 0.686591 1"/>
  </asset>
  <actuator>
    <position class="mjcf" name="waist_yaw_joint" joint="waist_yaw_joint" forcerange="-96 96" inheritrange="1"/>
    <position class="mjcf" name="waist_left_joint" joint="waist_left_joint" forcerange="-96 96" inheritrange="1"/>
    <position class="mjcf" name="waist_right_joint" joint="waist_right_joint" forcerange="-96 96" inheritrange="1"/>
    <position class="mjcf" name="left_shoulder_pitch_joint" joint="left_shoulder_pitch_joint" forcerange="-70 70" inheritrange="1"/>
    <position class="mjcf" name="left_shoulder_roll_joint" joint="left_shoulder_roll_joint" forcerange="-70 70" inheritrange="1"/>
    <position class="mjcf" name="left_shoulder_yaw_joint" joint="left_shoulder_yaw_joint" forcerange="-23 23" inheritrange="1"/>
    <position class="mjcf" name="left_elbow_pitch_joint" joint="left_elbow_pitch_joint" forcerange="-23 23" inheritrange="1"/>
    <position class="mjcf" name="left_wrist_roll_joint" joint="left_wrist_roll_joint" forcerange="-23 23" inheritrange="1"/>
    <position class="mjcf" name="left_wrist_pitch_joint" joint="left_wrist_pitch_joint" forcerange="-4.8 4.8" inheritrange="1"/>
    <position class="mjcf" name="left_wrist_yaw_joint" joint="left_wrist_yaw_joint" forcerange="-4.8 4.8" inheritrange="1"/>
    <position class="mjcf" name="right_shoulder_pitch_joint" joint="right_shoulder_pitch_joint" forcerange="-70 70" inheritrange="1"/>
    <position class="mjcf" name="right_shoulder_roll_joint" joint="right_shoulder_roll_joint" forcerange="-70 70" inheritrange="1"/>
    <position class="mjcf" name="right_shoulder_yaw_joint" joint="right_shoulder_yaw_joint" forcerange="-23 23" inheritrange="1"/>
    <position class="mjcf" name="right_elbow_pitch_joint" joint="right_elbow_pitch_joint" forcerange="-23 23" inheritrange="1"/>
    <position class="mjcf" name="right_wrist_roll_joint" joint="right_wrist_roll_joint" forcerange="-23 23" inheritrange="1"/>
    <position class="mjcf" name="right_wrist_pitch_joint" joint="right_wrist_pitch_joint" forcerange="-4.8 4.8" inheritrange="1"/>
    <position class="mjcf" name="right_wrist_yaw_joint" joint="right_wrist_yaw_joint" forcerange="-4.8 4.8" inheritrange="1"/>
    <position class="mjcf" name="neck_yaw_joint" joint="neck_yaw_joint" forcerange="-4.8 4.8" inheritrange="1"/>
    <position class="mjcf" name="neck_roll_joint" joint="neck_roll_joint" forcerange="-4.8 4.8" inheritrange="1"/>
    <position class="mjcf" name="neck_pitch_joint" joint="neck_pitch_joint" forcerange="-4.8 4.8" inheritrange="1"/>
  </actuator>
  <sensor>
    <actuatorfrc name="u_waist_yaw_joint" actuator="waist_yaw_joint"/>
    <actuatorfrc name="u_waist_left_joint" actuator="waist_left_joint"/>
    <actuatorfrc name="u_waist_right_joint" actuator="waist_right_joint"/>
    <actuatorfrc name="u_left_shoulder_pitch_joint" actuator="left_shoulder_pitch_joint"/>
    <actuatorfrc name="u_left_shoulder_roll_joint" actuator="left_shoulder_roll_joint"/>
    <actuatorfrc name="u_left_shoulder_yaw_joint" actuator="left_shoulder_yaw_joint"/>
    <actuatorfrc name="u_left_elbow_pitch_joint" actuator="left_elbow_pitch_joint"/>
    <actuatorfrc name="u_left_wrist_roll_joint" actuator="left_wrist_roll_joint"/>
    <actuatorfrc name="u_left_wrist_pitch_joint" actuator="left_wrist_pitch_joint"/>
    <actuatorfrc name="u_left_wrist_yaw_joint" actuator="left_wrist_yaw_joint"/>
    <actuatorfrc name="u_right_shoulder_pitch_joint" actuator="right_shoulder_pitch_joint"/>
    <actuatorfrc name="u_right_shoulder_roll_joint" actuator="right_shoulder_roll_joint"/>
    <actuatorfrc name="u_right_shoulder_yaw_joint" actuator="right_shoulder_yaw_joint"/>
    <actuatorfrc name="u_right_elbow_pitch_joint" actuator="right_elbow_pitch_joint"/>
    <actuatorfrc name="u_right_wrist_roll_joint" actuator="right_wrist_roll_joint"/>
    <actuatorfrc name="u_right_wrist_pitch_joint" actuator="right_wrist_pitch_joint"/>
    <actuatorfrc name="u_right_wrist_yaw_joint" actuator="right_wrist_yaw_joint"/>
    <actuatorfrc name="u_neck_yaw_joint" actuator="neck_yaw_joint"/>
    <actuatorfrc name="u_neck_roll_joint" actuator="neck_roll_joint"/>
    <actuatorfrc name="u_neck_pitch_joint" actuator="neck_pitch_joint"/>
  </sensor>

  <contact>
    <exclude body1="chest_link" body2="waist_yaw_link"/>
    <exclude body1="waist_yaw_link" body2="waist_left_passive_link"/>
    <exclude body1="waist_yaw_link" body2="waist_right_passive_link"/>

    <exclude body1="neck_pitch_link" body2="neck_yaw_link"/>

    <exclude body1="left_wrist_roll_link" body2="left_wrist_yaw_link"/>
    <exclude body1="right_wrist_roll_link" body2="right_wrist_yaw_link"/>
  </contact>
  <equality>
    <connect site1="closing_waist_left_passive2_joint_1" site2="closing_waist_left_passive2_joint_2" solref="0.002 1" solimp="0.9 0.9 0.01"/>
    <connect site1="closing_waist_right_passive2_joint_1" site2="closing_waist_right_passive2_joint_2" solref="0.002 1" solimp="0.9 0.9 0.01"/>
  </equality>
</mujoco>
