<?xml version='1.0' encoding='utf-8'?>
<mujoco model="mjcf">
  <compiler angle="radian" meshdir="../assets" autolimits="true" />
  <default>
    <default class="mjcf">
      <joint frictionloss="0.1" armature="0.005" />
      <position kp="50" dampratio="1" />
      <default class="visual">
        <geom type="mesh" contype="0" conaffinity="0" group="2" />
      </default>
      <default class="collision">
        <geom group="3" />
      </default>
    </default>
    <default class="wuji_hand">
      <joint armature="0.005" damping="0.05" frictionloss="0.01" />
    </default>
  </default>
  <worldbody>
    <body name="body_base_link" pos="0 0 0" quat="1 0 0 0" childclass="mjcf">
      <freejoint name="body_base_link_freejoint" />
      <inertial pos="-4.20726e-05 -9.03729e-06 0.422113" mass="76.8996" fullinertia="8.30255 7.32437 2.45005 -0.000118077 -0.000419172 -0.000193969" />
      <geom type="mesh" class="visual" pos="-4.20726e-05 -9.03729e-06 0.422113" quat="1 0 0 0" mesh="body_base_link_visual" material="body_base_link_visual_material" />
      <geom type="mesh" class="collision" pos="-4.20726e-05 -9.03729e-06 0.422113" quat="1 0 0 0" mesh="body_base_link_collision" material="body_base_link_collision_material" />
      <body name="waist_yaw_link" pos="-2.29257e-05 -5.21767e-07 1.08679" quat="0.707107 5.66021e-14 -1.58651e-13 0.707107">
        <joint axis="0 0 1" name="waist_yaw_joint" type="hinge" range="-3.1415926535898127 3.1415926535897736" armature="0.94096" damping="1.5" />
        <inertial pos="6.96649e-09 0.0176858 0.0185467" mass="0.318626" fullinertia="0.000368773 0.000823063 0.0010301 -9.75394e-11 1.12765e-11 -7.3433e-05" />
        <geom type="mesh" class="visual" pos="6.96649e-09 0.0176858 0.0185467" quat="0.707107 -5.66018e-14 1.58318e-13 -0.707107" mesh="waist_yaw_link_visual" material="waist_yaw_link_visual_material" />
        <geom type="mesh" class="collision" pos="6.96649e-09 0.0176858 0.0185467" quat="0.707107 -5.66018e-14 1.58318e-13 -0.707107" mesh="waist_yaw_link_collision" material="waist_yaw_link_collision_material" />
        <site group="3" name="closing_waist_left_passive2_joint_1" pos="0.088 0.05 0.035" quat="4.2981e-14 8.4942e-14 -0.707107 0.707107" />
        <site group="3" name="closing_waist_right_passive2_joint_1" pos="-0.088 0.05 0.035" quat="2.21002e-14 6.41383e-14 -0.707107 0.707107" />
        <body name="waist_roll_link" pos="-1.61684e-14 0.018 0.035" quat="0.707107 0.707107 -2.85327e-14 -6.97906e-14">
          <joint axis="0 0 1" name="waist_roll_passive_joint" type="hinge" range="-0.2617993878 0.2617993878" />
          <inertial pos="-5.81324e-13 -1.64791e-16 0.0177" mass="0.125178" fullinertia="1.24231e-05 2.84421e-05 2.01802e-05 9.2054e-19 -2.72412e-16 9.3826e-19" />
          <geom type="mesh" class="visual" pos="-5.81324e-13 0 0.0177" quat="0.5 -0.5 -0.5 -0.5" mesh="waist_roll_link_visual" material="waist_roll_link_visual_material" />
          <geom type="mesh" class="collision" pos="-5.81324e-13 0 0.0177" quat="0.5 -0.5 -0.5 -0.5" mesh="waist_roll_link_collision" material="waist_roll_link_collision_material" />
          <body name="chest_link" pos="-0.023 3.10862e-15 0.0177" quat="0.707107 -1.26301e-14 0.707107 -1.07475e-14">
            <joint axis="0 0 1" name="waist_pitch_passive_joint" type="hinge" range="-0.6108780951764704 0.5235987755983282" />
            <inertial pos="0.00598813 0.153501 0.0231031" mass="8.27946" fullinertia="0.119436 0.0529458 0.0772233 -0.00499883 4.07256e-05 -2.85322e-05" />
            <geom type="mesh" class="visual" pos="0.00598813 0.153501 0.0231031" quat="1.11705e-13 2.39721e-14 -0.707107 -0.707107" mesh="chest_link_visual" material="chest_link_visual_material" />
            <geom type="mesh" class="collision" pos="0.00598813 0.153501 0.0231031" quat="1.11705e-13 2.39721e-14 -0.707107 -0.707107" mesh="chest_link_collision" material="chest_link_collision_material" />
            <body name="waist_left_link" pos="8.59392e-12 0.07 0.1105" quat="2.90382e-14 0.707107 -0.707107 1.68577e-14">
              <joint axis="0 0 1" name="waist_left_joint" type="hinge" range="-0.6108780951764704 1.0471846942181424" armature="0.94096" damping="1.5" />
              <inertial pos="2.84367e-07 -0.0221506 -0.0066566" mass="0.0904052" fullinertia="8.85019e-05 3.64587e-05 0.000109689 6.68215e-10 1.74121e-10 -1.35386e-05" />
              <geom type="mesh" class="visual" pos="2.84367e-07 -0.0221506 -0.0066566" quat="0.5 -0.5 -0.5 0.5" mesh="waist_left_link_visual" material="waist_left_link_visual_material" />
              <geom type="mesh" class="collision" pos="2.84367e-07 -0.0221506 -0.0066566" quat="0.5 -0.5 -0.5 0.5" mesh="waist_left_link_collision" material="waist_left_link_collision_material" />
              <body name="waist_left_passive_link" pos="6.42849e-07 -0.05 -0.0205" quat="0.499997 0.500003 -0.499997 0.500003">
                <joint axis="0 0 1" name="waist_left_passive1_joint" type="ball" />
                <inertial pos="0.00782784 -0.0357958 -0.000151758" mass="0.029442" fullinertia="2.28696e-05 3.44733e-06 2.4643e-05 6.4948e-06 2.77059e-08 -9.07758e-08" />
                <geom type="mesh" class="visual" pos="0.00782784 -0.0357958 -0.000151758" quat="0.499997 -0.500003 0.500003 0.499997" mesh="waist_left_passive_link_visual" material="waist_left_passive_link_visual_material" />
                <geom type="mesh" class="collision" pos="0.00782784 -0.0357958 -0.000151758" quat="0.499997 -0.500003 0.500003 0.499997" mesh="waist_left_passive_link_collision" material="waist_left_passive_link_collision_material" />
                <site group="3" name="closing_waist_left_passive2_joint_2" pos="0.02 -0.0699994 -0.0002991" quat="0.00206636 -0.999998 -5.23666e-07 0.000245262" />
              </body>
            </body>
            <body name="waist_right_link" pos="-8.58013e-12 0.07 -0.0645" quat="0.707107 -2.92654e-14 -1.69864e-14 -0.707107">
              <joint axis="0 0 1" name="waist_right_joint" type="hinge" range="-1.047184694220563 0.61087809517405" armature="0.94096" damping="1.5" />
              <inertial pos="2.85212e-07 0.0221506 -0.0066566" mass="0.0904052" fullinertia="8.85019e-05 3.64587e-05 0.000109689 -6.70022e-10 1.7401e-10 1.35386e-05" />
              <geom type="mesh" class="visual" pos="2.85212e-07 0.0221506 -0.0066566" quat="0.5 0.5 -0.5 -0.5" mesh="waist_right_link_visual" material="waist_right_link_visual_material" />
              <geom type="mesh" class="collision" pos="2.85212e-07 0.0221506 -0.0066566" quat="0.5 0.5 -0.5 -0.5" mesh="waist_right_link_collision" material="waist_right_link_collision_material" />
              <body name="waist_right_passive_link" pos="6.42849e-07 0.05 -0.0205" quat="0.500003 -0.499997 0.500003 0.499997">
                <joint axis="0 0 1" name="waist_right_passive1_joint" type="ball" />
                <inertial pos="-0.00782784 -0.0357958 -0.000148717" mass="0.029442" fullinertia="2.28696e-05 3.44734e-06 2.4643e-05 -6.4948e-06 -2.76119e-08 -9.13537e-08" />
                <geom type="mesh" class="visual" pos="-0.00782784 -0.0357958 -0.000148717" quat="0.499997 -0.500003 0.500003 0.499997" mesh="waist_right_passive_link_visual" material="waist_right_passive_link_visual_material" />
                <geom type="mesh" class="collision" pos="-0.00782784 -0.0357958 -0.000148717" quat="0.499997 -0.500003 0.500003 0.499997" mesh="waist_right_passive_link_collision" material="waist_right_passive_link_collision_material" />
                <site group="3" name="closing_waist_right_passive2_joint_2" pos="-0.02 -0.0699994 -0.0002991" quat="0.0018833 -0.999998 1.8925e-06 -0.000885968" />
              </body>
            </body>
            <body name="left_shoulder_pitch_link" pos="0.01443 0.247814 0.160316" quat="0.996195 -0.0871557 2.77556e-15 -3.08012e-16">
              <joint axis="0 0 1" name="left_shoulder_pitch_joint" type="hinge" range="-2.356194490192352 2.3561944901923377" armature="0.70637" damping="1.5" />
              <inertial pos="0.00445247 -0.00401905 0.0555302" mass="1.61013" fullinertia="0.00169156 0.00169393 0.00136864 -6.04835e-05 -1.91261e-05 3.84532e-05" />
              <geom type="mesh" class="visual" pos="0.00445247 -0.00401905 0.0555302" quat="1.07258e-13 3.61288e-14 -0.642788 -0.766044" mesh="left_shoulder_pitch_link_visual" material="left_shoulder_pitch_link_visual_material" />
              <geom type="mesh" class="collision" pos="0.00445247 -0.00401905 0.0555302" quat="1.07258e-13 3.61288e-14 -0.642788 -0.766044" mesh="left_shoulder_pitch_link_collision" material="left_shoulder_pitch_link_collision_material" />
              <body name="left_shoulder_roll_link" pos="0.0311127 -0.0311127 0.06" quat="0.701057 0.560986 0.430459 0.092296">
                <joint axis="0 0 1" name="left_shoulder_roll_joint" type="hinge" range="-1.0471975511971885 1.047197551196007" armature="0.70637" damping="1.5" />
                <inertial pos="-0.113042 1.86932e-05 -0.0428809" mass="1.23133" fullinertia="0.0010626 0.00194814 0.00180368 -4.20698e-07 -5.54234e-06 1.63617e-07" />
                <geom type="mesh" class="visual" pos="-0.113042 1.86932e-05 -0.0428809" quat="0.347397 -0.270424 0.880371 0.176447" mesh="left_shoulder_roll_link_visual" material="left_shoulder_roll_link_visual_material" />
                <geom type="mesh" class="collision" pos="-0.113042 1.86932e-05 -0.0428809" quat="0.347397 -0.270424 0.880371 0.176447" mesh="left_shoulder_roll_link_collision" material="left_shoulder_roll_link_collision_material" />
                <body name="left_shoulder_yaw_link" pos="-0.16 -8.10463e-14 -0.043" quat="0.5 0.5 -0.5 -0.5">
                  <joint axis="0 0 1" name="left_shoulder_yaw_joint" type="hinge" range="-1.5707963267949232 1.57079632679487" armature="0.12749" damping="1.5" />
                  <inertial pos="0.00144727 0.00119292 0.0961527" mass="1.32768" fullinertia="0.00221382 0.00222585 0.000940724 4.50044e-07 -2.45225e-05 5.42601e-05" />
                  <geom type="mesh" class="visual" pos="0.00144727 0.00119292 0.0961527" quat="0.489922 0.660873 -0.566895 0.0430516" mesh="left_shoulder_yaw_link_visual" material="left_shoulder_yaw_link_visual_material" />
                  <geom type="mesh" class="collision" pos="0.00144727 0.00119292 0.0961527" quat="0.489922 0.660873 -0.566895 0.0430516" mesh="left_shoulder_yaw_link_collision" material="left_shoulder_yaw_link_collision_material" />
                  <body name="left_elbow_pitch_link" pos="0.0405 -2.60902e-14 0.11" quat="0.587938 0.392847 0.587938 0.392847">
                    <joint axis="0 0 1" name="left_elbow_pitch_joint" type="hinge" range="-1.1780972450965326 1.1780972450958123" armature="0.12749" damping="1.5" />
                    <inertial pos="-0.0818905 0.000647018 -0.0402032" mass="1.17763" fullinertia="0.00094916 0.00125269 0.00115385 -1.58858e-05 -3.04234e-05 7.52023e-08" />
                    <geom type="mesh" class="visual" pos="-0.0818905 0.000647018 -0.0402032" quat="0.23128 -0.0519277 -0.864052 0.444102" mesh="left_elbow_pitch_link_visual" material="left_elbow_pitch_link_visual_material" />
                    <geom type="mesh" class="collision" pos="-0.0818905 0.000647018 -0.0402032" quat="0.23128 -0.0519277 -0.864052 0.444102" mesh="left_elbow_pitch_link_collision" material="left_elbow_pitch_link_collision_material" />
                    <body name="left_wrist_roll_link" pos="-0.124 -2.85327e-14 -0.0405" quat="0.5 0.5 -0.5 -0.5">
                      <joint axis="0 0 1" name="left_wrist_roll_joint" type="hinge" range="-1.5707963267943397 1.5707963267954534" armature="0.12749" damping="1.5" />
                      <inertial pos="-7.42693e-11 0.000278379 0.0385646" mass="0.404705" fullinertia="0.000421826 0.00034236 0.000208792 -6.65218e-12 -1.68616e-12 1.62664e-05" />
                      <geom type="mesh" class="visual" pos="-7.42691e-11 0.000278379 0.0385646" quat="0.299651 0.512473 -0.120299 0.795681" mesh="left_wrist_roll_link_visual" material="left_wrist_roll_link_visual_material" />
                      <geom type="mesh" class="collision" pos="-7.42691e-11 0.000278379 0.0385646" quat="0.299651 0.512473 -0.120299 0.795681" mesh="left_wrist_roll_link_collision" material="left_wrist_roll_link_collision_material" />
                      <body name="left_wrist_pitch_link" pos="-5.44009e-15 -0.022 0.099" quat="1.6738e-13 -2.03769e-13 0.707107 0.707107">
                        <joint axis="0 0 1" name="left_wrist_pitch_joint" type="hinge" range="-0.7853981633974554 0.7853981633974412" armature="0.3" damping="1.5" />
                        <inertial pos="-0.00106391 -2.33324e-11 0.0219286" mass="0.304398" fullinertia="8.08739e-05 0.000118571 0.000107519 1.64597e-11 5.38408e-07 4.41999e-12" />
                        <geom type="mesh" class="visual" pos="-0.00106391 -2.33324e-11 0.0219286" quat="0.477567 -0.647696 -0.574259 0.150488" mesh="left_wrist_pitch_link_visual" material="left_wrist_pitch_link_visual_material" />
                        <geom type="mesh" class="collision" pos="-0.00106391 -2.33324e-11 0.0219286" quat="0.477567 -0.647696 -0.574259 0.150488" mesh="left_wrist_pitch_link_collision" material="left_wrist_pitch_link_collision_material" />
                        <body name="left_wrist_yaw_link" pos="-0.03155 2.88658e-15 0.022" quat="0.707107 -1.17207e-13 0.707107 -1.11418e-13">
                          <joint axis="0 0 1" name="left_wrist_yaw_joint" type="hinge" range="-0.7853981633971223 1.5707963267952225" armature="0.3" damping="1.5" />
                          <inertial pos="-1.12308e-10 0.0267049 0.0302175" mass="0.0547065" fullinertia="5.07331e-05 4.43376e-05 2.14007e-05 3.12122e-13 -2.86228e-11 2.44558e-07" />
                          <geom type="mesh" class="visual" pos="-1.12308e-10 0.0267049 0.0302175" quat="0.0683713 0.564401 0.743753 0.351579" mesh="left_wrist_yaw_link_visual" material="left_wrist_yaw_link_visual_material" />
                          <geom type="mesh" class="collision" pos="-1.12308e-10 0.0267049 0.0302175" quat="0.0683713 0.564401 0.743753 0.351579" mesh="left_wrist_yaw_link_collision" material="left_wrist_yaw_link_collision_material" />
                          <site group="3" name="left_hand" pos="-2.07612e-14 0.0485 0.03005" quat="4.10783e-15 -5.72223e-15 0.707107 0.707107" />
                          <body name="left_wuji_hand_mount" pos="-2.07612e-14 0.0485 0.03005" quat="4.10783e-15 -5.72223e-15 0.707107 0.707107" childclass="wuji_hand">
                            <inertial pos="-0.0029787944008666 -0.000452551657325986 0.036654705440297" mass="0.16914" fullinertia="0.00014 9.47e-05 6e-05 2.54e-06 6.91e-06 -6.63e-06" />
                            <geom type="mesh" contype="0" conaffinity="0" group="1" density="0" rgba="0.6 0.8 0.9 1" mesh="left_palm_link" />
                            <geom type="mesh" rgba="0.6 0.8 0.9 1" mesh="left_palm_link" contype="1" conaffinity="1" />
                            <body name="left_finger1_link1" pos="0.00843985 -0.0205866 0.0288928" quat="0.157842 -0.148336 0.668565 0.711409">
                              <inertial pos="-0.00312584 0.00124335 -0.00755623" quat="0.904243 0.21652 0.0443878 -0.365368" mass="0.0075" diaginertia="3.37599e-07 3.01198e-07 2.11203e-07" />
                              <joint name="left_finger1_joint1" pos="0 0 0" axis="0 1 0" range="0.0583 1.5941" actuatorfrcrange="-0.4452 0.4452" />
                              <geom type="mesh" contype="0" conaffinity="0" group="1" density="0" rgba="0.7 0.7 0.7 1" mesh="left_finger1_link1" />
                              <geom type="mesh" rgba="0.7 0.7 0.7 1" mesh="left_finger1_link1" contype="0" conaffinity="0" />
                              <body name="left_finger1_link2" pos="-0.0054483 0.0058191 -0.01388" quat="0.678684 0.174096 -0.067811 0.710268">
                                <inertial pos="-0.00142783 1.46615e-05 -0.0156343" quat="0.815906 0.0024483 -0.00462559 0.57816" mass="0.0248" diaginertia="2.81725e-06 2.75299e-06 6.79766e-07" />
                                <joint name="left_finger1_joint2" pos="0 0 0" axis="0 -1 0" range="-0.1199 0.9335" actuatorfrcrange="-0.4259 0.4259" />
                                <geom type="mesh" contype="0" conaffinity="0" group="1" density="0" rgba="0.9 0.8 0.6 1" mesh="left_finger1_link2" />
                                <geom type="mesh" rgba="0.9 0.8 0.6 1" mesh="left_finger1_link2" contype="2" conaffinity="2" />
                                <body name="left_finger1_link3" pos="-0.000846961 0.000991504 -0.0346563" quat="0.577941 0.0144097 -0.0101665 -0.815888">
                                  <inertial pos="0.0011232 1.573e-05 -0.0130566" quat="0.999951 0 0.00989566 0" mass="0.0165" diaginertia="1.4604e-06 1.42e-06 4.49604e-07" />
                                  <joint name="left_finger1_joint3" pos="0 0 0" axis="0 1 0" range="-0.4646 1.5639" actuatorfrcrange="-0.1888 0.1888" />
                                  <geom type="mesh" contype="0" conaffinity="0" group="1" density="0" rgba="0.6 0.8 0.9 1" mesh="left_finger1_link3" />
                                  <geom type="mesh" rgba="0.6 0.8 0.9 1" mesh="left_finger1_link3" contype="1" conaffinity="1" />
                                  <body name="left_finger1_link4" pos="0 0 -0.0295">
                                    <inertial pos="0.00143098 2.14273e-05 -0.0111038" quat="0.706889 -0.0413139 -0.0421609 0.704858" mass="0.0206" diaginertia="2.46834e-06 2.44702e-06 7.6132e-07" />
                                    <joint name="left_finger1_joint4" pos="0 0 0" axis="0 1 0" range="-0.457 1.5684" actuatorfrcrange="-0.1468 0.1468" />
                                    <geom type="mesh" contype="0" conaffinity="0" group="1" density="0" rgba="0.6 0.8 0.9 1" mesh="left_finger1_link4" />
                                    <geom type="mesh" rgba="0.6 0.8 0.9 1" mesh="left_finger1_link4" contype="1" conaffinity="1" />
                                    <geom pos="0.00105 0 -0.0235" quat="0 0 -1 0" type="mesh" contype="0" conaffinity="0" group="1" density="0" rgba="0.6 0.8 0.9 1" mesh="left_finger1_tip_link" />
                                    <geom pos="0.00105 0 -0.0235" quat="0 0 -1 0" type="mesh" rgba="0.6 0.8 0.9 1" mesh="left_finger1_tip_link" contype="1" conaffinity="1" />
                                  </body>
                                </body>
                              </body>
                            </body>
                            <body name="left_finger2_link1" pos="-0.00587009 -0.0294339 0.0919165" quat="0.9921 0.056257 -0.00634791 0.111946">
                              <inertial pos="-0.00134244 -5.65576e-09 0.000258175" quat="0.92388 0 0.382683 0" mass="0.0032" diaginertia="1.1e-07 7e-08 5e-08" />
                              <joint name="left_finger2_joint1" pos="0 0 0" axis="0 1 0" range="-0.156 1.5619" actuatorfrcrange="-0.6188 0.6188" />
                              <geom type="mesh" contype="0" conaffinity="0" group="1" density="0" rgba="0.7 0.7 0.7 1" mesh="left_finger2_link1" />
                              <geom type="mesh" rgba="0.7 0.7 0.7 1" mesh="left_finger2_link1" contype="0" conaffinity="0" />
                              <body name="left_finger2_link2" pos="0.00038954 0 0.0040223" quat="0.999733 0 -0.0231118 0">
                                <inertial pos="-0.00453252 4.38298e-07 0.020911" quat="0.70703 0.0104245 0.0104245 0.70703" mass="0.033" diaginertia="6.34e-06 6.31472e-06 8.85281e-07" />
                                <joint name="left_finger2_joint2" pos="0 0 0" axis="-1 0 0" range="-0.4095 0.2921" actuatorfrcrange="-0.1822 0.1822" />
                                <geom type="mesh" contype="0" conaffinity="0" group="1" density="0" rgba="0.9 0.8 0.6 1" mesh="left_finger2_link2" />
                                <geom type="mesh" rgba="0.9 0.8 0.6 1" mesh="left_finger2_link2" contype="2" conaffinity="2" />
                                <body name="left_finger2_link3" pos="-0.00312503 0.000100282 0.0436177" quat="1 0 0 0.000134306">
                                  <inertial pos="-0.00112187 -6.72383e-05 0.0157188" quat="0.999892 0 -0.0146884 0" mass="0.0165" diaginertia="1.47088e-06 1.44e-06 4.49118e-07" />
                                  <joint name="left_finger2_joint3" pos="0 0 0" axis="0 1 0" range="-0.4839 1.5466" actuatorfrcrange="-0.2251 0.2251" />
                                  <geom type="mesh" contype="0" conaffinity="0" group="1" density="0" rgba="0.6 0.8 0.9 1" mesh="left_finger2_link3" />
                                  <geom type="mesh" rgba="0.6 0.8 0.9 1" mesh="left_finger2_link3" contype="1" conaffinity="1" />
                                  <body name="left_finger2_link4" pos="0 0 0.0295">
                                    <inertial pos="-0.000577493 -0.000439345 0.0077094" quat="0.996472 0.0222479 -0.0379654 0.0714678" mass="0.01718" diaginertia="1.58791e-06 1.49887e-06 4.38452e-07" />
                                    <joint name="left_finger2_joint4" pos="0 0 0" axis="0 1 0" range="-0.4723 1.5754" actuatorfrcrange="-0.217 0.217" />
                                    <geom type="mesh" contype="0" conaffinity="0" group="1" density="0" rgba="0.6 0.8 0.9 1" mesh="left_finger2_link4" />
                                    <geom type="mesh" rgba="0.6 0.8 0.9 1" mesh="left_finger2_link4" contype="1" conaffinity="1" />
                                    <geom pos="-0.002 -0.0001 0.0239466" type="mesh" contype="0" conaffinity="0" group="1" density="0" rgba="0.6 0.8 0.9 1" mesh="left_finger2_tip_link" />
                                    <geom pos="-0.002 -0.0001 0.0239466" type="mesh" rgba="0.6 0.8 0.9 1" mesh="left_finger2_tip_link" contype="1" conaffinity="1" />
                                  </body>
                                </body>
                              </body>
                            </body>
                            <body name="left_finger3_link1" pos="-0.01046 -0.0074615 0.089544" quat="1 2.53465e-05 -7.34339e-09 -0.00028972">
                              <inertial pos="-0.0013519 -1.49581e-08 0.000202846" quat="0.92388 0 0.382683 0" mass="0.0032" diaginertia="1.1e-07 7e-08 5e-08" />
                              <joint name="left_finger3_joint1" pos="0 0 0" axis="0 1 0" range="-0.1569 1.5536" actuatorfrcrange="-0.6494 0.6494" />
                              <geom type="mesh" contype="0" conaffinity="0" group="1" density="0" rgba="0.7 0.7 0.7 1" mesh="left_finger3_link1" />
                              <geom type="mesh" rgba="0.7 0.7 0.7 1" mesh="left_finger3_link1" contype="0" conaffinity="0" />
                              <body name="left_finger3_link2" pos="0.000224189 0 0.0040349" quat="0.999048 0 -0.0436194 0">
                                <inertial pos="-0.0063378 3.07421e-06 0.0204364" quat="0.70703 0.0104245 0.0104245 0.70703" mass="0.033" diaginertia="6.34e-06 6.31472e-06 8.85281e-07" />
                                <joint name="left_finger3_joint2" pos="0 0 0" axis="-1 0 0" range="-0.3977 0.3115" actuatorfrcrange="-0.1827 0.1827" />
                                <geom type="mesh" contype="0" conaffinity="0" group="1" density="0" rgba="0.9 0.8 0.6 1" mesh="left_finger3_link2" />
                                <geom type="mesh" rgba="0.9 0.8 0.6 1" mesh="left_finger3_link2" contype="2" conaffinity="2" />
                                <body name="left_finger3_link3" pos="-0.00312503 0.000100283 0.0436177" quat="1 0 0 0.000134306">
                                  <inertial pos="-0.00112187 -6.72196e-05 0.0157188" quat="0.999892 0 -0.0146884 0" mass="0.0165" diaginertia="1.47088e-06 1.44e-06 4.49118e-07" />
                                  <joint name="left_finger3_joint3" pos="0 0 0" axis="0 1 0" range="-0.4847 1.5411" actuatorfrcrange="-0.2078 0.2078" />
                                  <geom type="mesh" contype="0" conaffinity="0" group="1" density="0" rgba="0.6 0.8 0.9 1" mesh="left_finger3_link3" />
                                  <geom type="mesh" rgba="0.6 0.8 0.9 1" mesh="left_finger3_link3" contype="1" conaffinity="1" />
                                  <body name="left_finger3_link4" pos="0 0 0.0295">
                                    <inertial pos="-0.000569212 -0.000437935 0.00770941" quat="0.99642 0.0221379 -0.0373581 0.0725293" mass="0.01718" diaginertia="1.58767e-06 1.49921e-06 4.39012e-07" />
                                    <joint name="left_finger3_joint4" pos="0 0 0" axis="0 1 0" range="-0.4671 1.5788" actuatorfrcrange="-0.2018 0.2018" />
                                    <geom type="mesh" contype="0" conaffinity="0" group="1" density="0" rgba="0.6 0.8 0.9 1" mesh="left_finger3_link4" />
                                    <geom type="mesh" rgba="0.6 0.8 0.9 1" mesh="left_finger3_link4" contype="1" conaffinity="1" />
                                    <geom pos="-0.002 -0.0001 0.0239466" type="mesh" contype="0" conaffinity="0" group="1" density="0" rgba="0.6 0.8 0.9 1" mesh="left_finger3_tip_link" />
                                    <geom pos="-0.002 -0.0001 0.0239466" type="mesh" rgba="0.6 0.8 0.9 1" mesh="left_finger3_tip_link" contype="1" conaffinity="1" />
                                  </body>
                                </body>
                              </body>
                            </body>
                            <body name="left_finger4_link1" pos="-0.0076649 0.013712 0.084429" quat="0.998613 -0.0449975 0.00123051 -0.0273084">
                              <inertial pos="-0.00135119 -9.65326e-09 0.000207529" quat="0.92388 0 0.382683 0" mass="0.0032" diaginertia="1.1e-07 7e-08 5e-08" />
                              <joint name="left_finger4_joint1" pos="0 0 0" axis="0 1 0" range="-0.1507 1.5636" actuatorfrcrange="-0.6389 0.6389" />
                              <geom type="mesh" contype="0" conaffinity="0" group="1" density="0" rgba="0.7 0.7 0.7 1" mesh="left_finger4_link1" />
                              <geom type="mesh" rgba="0.7 0.7 0.7 1" mesh="left_finger4_link1" contype="0" conaffinity="0" />
                              <body name="left_finger4_link2" pos="0.000238272 0 0.00403409" quat="0.999123 0 -0.0418757 0">
                                <inertial pos="-0.00452747 0.000214165 0.020911" quat="0.70703 0.0104245 0.0104245 0.70703" mass="0.033" diaginertia="6.34e-06 6.31472e-06 8.85281e-07" />
                                <joint name="left_finger4_joint2" pos="0 0 0" axis="-1 0 0" range="-0.4101 0.3014" actuatorfrcrange="-0.1832 0.1832" />
                                <geom type="mesh" contype="0" conaffinity="0" group="1" density="0" rgba="0.9 0.8 0.6 1" mesh="left_finger4_link2" />
                                <geom type="mesh" rgba="0.9 0.8 0.6 1" mesh="left_finger4_link2" contype="2" conaffinity="2" />
                                <body name="left_finger4_link3" pos="-0.00312503 0.000100282 0.0436177" quat="1 0 0 0.000134312">
                                  <inertial pos="-0.00112188 -6.72061e-05 0.0157188" quat="0.999892 0 -0.0146884 0" mass="0.0165" diaginertia="1.47088e-06 1.44e-06 4.49118e-07" />
                                  <joint name="left_finger4_joint3" pos="0 0 0" axis="0 1 0" range="-0.4747 1.5526" actuatorfrcrange="-0.2249 0.2249" />
                                  <geom type="mesh" contype="0" conaffinity="0" group="1" density="0" rgba="0.6 0.8 0.9 1" mesh="left_finger4_link3" />
                                  <geom type="mesh" rgba="0.6 0.8 0.9 1" mesh="left_finger4_link3" contype="1" conaffinity="1" />
                                  <body name="left_finger4_link4" pos="0 0 0.0295">
                                    <inertial pos="-0.000569623 -0.000441093 0.00770942" quat="0.996378 0.022381 -0.0374127 0.0730138" mass="0.01718" diaginertia="1.58788e-06 1.49922e-06 4.39096e-07" />
                                    <joint name="left_finger4_joint4" pos="0 0 0" axis="0 1 0" range="-0.4729 1.5718" actuatorfrcrange="-0.2044 0.2044" />
                                    <geom type="mesh" contype="0" conaffinity="0" group="1" density="0" rgba="0.6 0.8 0.9 1" mesh="left_finger4_link4" />
                                    <geom type="mesh" rgba="0.6 0.8 0.9 1" mesh="left_finger4_link4" contype="1" conaffinity="1" />
                                    <geom pos="-0.002 -0.0001 0.0239466" type="mesh" contype="0" conaffinity="0" group="1" density="0" rgba="0.6 0.8 0.9 1" mesh="left_finger4_tip_link" />
                                    <geom pos="-0.002 -0.0001 0.0239466" type="mesh" rgba="0.6 0.8 0.9 1" mesh="left_finger4_tip_link" contype="1" conaffinity="1" />
                                  </body>
                                </body>
                              </body>
                            </body>
                            <body name="left_finger5_link1" pos="-0.00226865 0.0340011 0.0742813" quat="0.991575 -0.0953097 0.00839343 -0.0873229">
                              <inertial pos="-0.00135329 -2.35789e-08 0.000193347" quat="0.92388 0 0.382683 0" mass="0.0032" diaginertia="1.1e-07 7e-08 5e-08" />
                              <joint name="left_finger5_joint1" pos="0 0 0" axis="0 1 0" range="-0.1578 1.5632" actuatorfrcrange="-0.6441 0.6441" />
                              <geom type="mesh" contype="0" conaffinity="0" group="1" density="0" rgba="0.7 0.7 0.7 1" mesh="left_finger5_link1" />
                              <geom type="mesh" rgba="0.7 0.7 0.7 1" mesh="left_finger5_link1" contype="0" conaffinity="0" />
                              <body name="left_finger5_link2" pos="0.000196015 0 0.00403637" quat="0.99889 0 -0.0471065 0">
                                <inertial pos="-0.00453253 4.36745e-07 0.020911" quat="0.70703 0.0104245 0.0104245 0.70703" mass="0.033" diaginertia="6.34e-06 6.31472e-06 8.85281e-07" />
                                <joint name="left_finger5_joint2" pos="0 0 0" axis="-1 0 0" range="-0.4103 0.2949" actuatorfrcrange="-0.1798 0.1798" />
                                <geom type="mesh" contype="0" conaffinity="0" group="1" density="0" rgba="0.9 0.8 0.6 1" mesh="left_finger5_link2" />
                                <geom type="mesh" rgba="0.9 0.8 0.6 1" mesh="left_finger5_link2" contype="2" conaffinity="2" />
                                <body name="left_finger5_link3" pos="-0.00312503 0.000100283 0.0436177" quat="1 0 0 0.000134306">
                                  <inertial pos="-0.00112188 -6.71933e-05 0.0157188" quat="0.999892 0 -0.0146884 0" mass="0.0165" diaginertia="1.47088e-06 1.44e-06 4.49118e-07" />
                                  <joint name="left_finger5_joint3" pos="0 0 0" axis="0 1 0" range="-0.4733 1.556" actuatorfrcrange="-0.2384 0.2384" />
                                  <geom type="mesh" contype="0" conaffinity="0" group="1" density="0" rgba="0.6 0.8 0.9 1" mesh="left_finger5_link3" />
                                  <geom type="mesh" rgba="0.6 0.8 0.9 1" mesh="left_finger5_link3" contype="1" conaffinity="1" />
                                  <body name="left_finger5_link4" pos="0 0 0.0295">
                                    <inertial pos="-0.000572786 -0.000437032 0.00770942" quat="0.996465 0.0220675 -0.0376073 0.0718051" mass="0.01718" diaginertia="1.58768e-06 1.49906e-06 4.38715e-07" />
                                    <joint name="left_finger5_joint4" pos="0 0 0" axis="0 1 0" range="-0.4662 1.576" actuatorfrcrange="-0.1866 0.1866" />
                                    <geom type="mesh" contype="0" conaffinity="0" group="1" density="0" rgba="0.6 0.8 0.9 1" mesh="left_finger5_link4" />
                                    <geom type="mesh" rgba="0.6 0.8 0.9 1" mesh="left_finger5_link4" contype="1" conaffinity="1" />
                                    <geom pos="-0.002 -0.0001 0.0239466" type="mesh" contype="0" conaffinity="0" group="1" density="0" rgba="0.6 0.8 0.9 1" mesh="left_finger5_tip_link" />
                                    <geom pos="-0.002 -0.0001 0.0239466" type="mesh" rgba="0.6 0.8 0.9 1" mesh="left_finger5_tip_link" contype="1" conaffinity="1" />
                                  </body>
                                </body>
                              </body>
                            </body>
                          </body>
                        </body>
                      </body>
                    </body>
                  </body>
                </body>
              </body>
            </body>
            <body name="right_shoulder_pitch_link" pos="0.01443 0.247814 -0.114316" quat="2.5912e-14 -1.62171e-14 -0.996195 -0.0871557">
              <joint axis="0 0 1" name="right_shoulder_pitch_joint" type="hinge" range="-2.356194490192399 2.3561944901922907" armature="0.70637" damping="1.5" />
              <inertial pos="-0.00435028 -0.00412125 0.0556137" mass="1.61012" fullinertia="0.00169967 0.00168831 0.00136875 6.05419e-05 2.11785e-05 4.20073e-05" />
              <geom type="mesh" class="visual" pos="-0.00435028 -0.00412125 0.0556137" quat="0.766044 -0.642788 1.0647e-13 -4.39387e-14" mesh="right_shoulder_pitch_link_visual" material="right_shoulder_pitch_link_visual_material" />
              <geom type="mesh" class="collision" pos="-0.00435028 -0.00412125 0.0556137" quat="0.766044 -0.642788 1.0647e-13 -4.39387e-14" mesh="right_shoulder_pitch_link_collision" material="right_shoulder_pitch_link_collision_material" />
              <body name="right_shoulder_roll_link" pos="-0.0311127 -0.0311127 0.06" quat="0.092296 -0.430459 -0.560986 0.701057">
                <joint axis="0 0 1" name="right_shoulder_roll_joint" type="hinge" range="-1.0471975511962044 1.0471975511969909" armature="0.70637" damping="1.5" />
                <inertial pos="-0.113042 -1.86911e-05 -0.0428187" mass="1.23133" fullinertia="0.00106257 0.00194811 0.00180368 4.20577e-07 -7.26269e-06 1.56805e-07" />
                <geom type="mesh" class="visual" pos="-0.113042 -1.86911e-05 -0.0428187" quat="0.347397 0.270424 0.880371 -0.176447" mesh="right_shoulder_roll_link_visual" material="right_shoulder_roll_link_visual_material" />
                <geom type="mesh" class="collision" pos="-0.113042 -1.86911e-05 -0.0428187" quat="0.347397 0.270424 0.880371 -0.176447" mesh="right_shoulder_roll_link_collision" material="right_shoulder_roll_link_collision_material" />
                <body name="right_shoulder_yaw_link" pos="-0.16 3.39728e-14 -0.043" quat="0.5 0.5 -0.5 -0.5">
                  <joint axis="0 0 1" name="right_shoulder_yaw_joint" type="hinge" range="-1.5707963267949383 1.5707963267948548" armature="0.12749" damping="1.5" />
                  <inertial pos="-0.00144725 0.00119294 0.096095" mass="1.32768" fullinertia="0.0022117 0.00222373 0.000940725 -4.50574e-07 2.68485e-05 5.44907e-05" />
                  <geom type="mesh" class="visual" pos="-0.00144725 0.00119294 0.096095" quat="0.0430516 0.566895 -0.660873 0.489922" mesh="right_shoulder_yaw_link_visual" material="right_shoulder_yaw_link_visual_material" />
                  <geom type="mesh" class="collision" pos="-0.00144725 0.00119294 0.096095" quat="0.0430516 0.566895 -0.660873 0.489922" mesh="right_shoulder_yaw_link_collision" material="right_shoulder_yaw_link_collision_material" />
                  <body name="right_elbow_pitch_link" pos="-0.0405 4.20775e-14 0.11" quat="0.392847 -0.587938 -0.392847 0.587938">
                    <joint axis="0 0 1" name="right_elbow_pitch_joint" type="hinge" range="-1.1780972450967344 1.1780972450956104" armature="0.12749" damping="1.5" />
                    <inertial pos="-0.0818905 -0.000712004 -0.0402032" mass="1.17763" fullinertia="0.000949056 0.00125269 0.00115375 1.79772e-05 -3.04229e-05 -4.18437e-07" />
                    <geom type="mesh" class="visual" pos="-0.0818905 -0.000712004 -0.0402032" quat="0.23128 0.0519277 -0.864052 -0.444102" mesh="right_elbow_pitch_link_visual" material="right_elbow_pitch_link_visual_material" />
                    <geom type="mesh" class="collision" pos="-0.0818905 -0.000712004 -0.0402032" quat="0.23128 0.0519277 -0.864052 -0.444102" mesh="right_elbow_pitch_link_collision" material="right_elbow_pitch_link_collision_material" />
                    <body name="right_wrist_roll_link" pos="-0.124 -6.69464e-14 -0.0405" quat="0.5 -0.5 -0.5 0.5">
                      <joint axis="0 0 1" name="right_wrist_roll_joint" type="hinge" range="-1.5707963267949197 1.5707963267948735" armature="0.12749" damping="1.5" />
                      <inertial pos="1.97018e-10 -0.000317914 0.0385646" mass="0.404705" fullinertia="0.000420807 0.00034236 0.000207773 -5.82532e-12 1.70915e-12 -1.57794e-05" />
                      <geom type="mesh" class="visual" pos="1.97018e-10 -0.000317914 0.0385646" quat="0.299651 -0.512473 -0.120299 -0.795681" mesh="right_wrist_roll_link_visual" material="right_wrist_roll_link_visual_material" />
                      <geom type="mesh" class="collision" pos="1.97018e-10 -0.000317914 0.0385646" quat="0.299651 -0.512473 -0.120299 -0.795681" mesh="right_wrist_roll_link_collision" material="right_wrist_roll_link_collision_material" />
                      <body name="right_wrist_ptich_link" pos="-1.22125e-15 0.022 0.099" quat="0.707107 0.707107 6.77236e-15 -7.48197e-15">
                        <joint axis="0 0 1" name="right_wrist_pitch_joint" type="hinge" range="-0.7853981633974678 0.7853981633974287" armature="0.3" damping="1.5" />
                        <inertial pos="-0.00106391 -1.95311e-10 0.0220599" mass="0.304398" fullinertia="8.08744e-05 0.000118571 0.000107519 3.53192e-13 -5.34681e-07 -9.46581e-11" />
                        <geom type="mesh" class="visual" pos="-0.00106391 -1.95311e-10 0.0220599" quat="0.150488 0.574259 0.647696 0.477567" mesh="right_wrist_ptich_link_visual" material="right_wrist_ptich_link_visual_material" />
                        <geom type="mesh" class="collision" pos="-0.00106391 -1.95311e-10 0.0220599" quat="0.150488 0.574259 0.647696 0.477567" mesh="right_wrist_ptich_link_collision" material="right_wrist_ptich_link_collision_material" />
                        <body name="right_wrist_yaw_link" pos="-0.03155 2.08722e-14 0.022" quat="0.707107 5.20535e-13 0.707107 1.48454e-13">
                          <joint axis="0 0 1" name="right_wrist_yaw_joint" type="hinge" range="-0.7853981633973852 1.5707963267949596" armature="0.3" damping="1.5" />
                          <inertial pos="-1.12277e-10 0.0267049 0.0302175" mass="0.0547065" fullinertia="5.07331e-05 4.43376e-05 2.14007e-05 3.12103e-13 -2.86228e-11 2.44558e-07" />
                          <geom type="mesh" class="visual" pos="-1.12277e-10 0.0267049 0.0302175" quat="0.564401 0.0683713 0.351579 0.743753" mesh="right_wrist_yaw_link_visual" material="right_wrist_yaw_link_visual_material" />
                          <geom type="mesh" class="collision" pos="-1.12277e-10 0.0267049 0.0302175" quat="0.564401 0.0683713 0.351579 0.743753" mesh="right_wrist_yaw_link_collision" material="right_wrist_yaw_link_collision_material" />
                          <site group="3" name="right_hand" pos="3.475e-14 0.0485 0.03005" quat="2.10942e-15 -2.17405e-14 -0.707107 -0.707107" />
                          <body name="right_wuji_hand_mount" pos="3.475e-14 0.0485 0.03005" quat="2.10942e-15 -2.17405e-14 -0.707107 -0.707107" childclass="wuji_hand">
                            <inertial pos="-0.0029795 0.00045572 0.036654" mass="0.16914" fullinertia="0.00014 9.47e-05 6e-05 2.54e-06 6.91e-06 -6.63e-06" />
                            <geom type="mesh" contype="0" conaffinity="0" group="1" density="0" rgba="0.6 0.8 0.9 1" mesh="right_palm_link" />
                            <geom type="mesh" rgba="0.6 0.8 0.9 1" mesh="right_palm_link" contype="1" conaffinity="1" />
                            <body name="right_finger1_link1" pos="0.0085244 0.020575 0.028712" quat="0.682219 -0.617669 0.0805047 -0.382859">
                              <inertial pos="-0.0024628 -0.0014428 0.0077802" quat="0.904243 0.21652 0.0443878 -0.365368" mass="0.0075" diaginertia="3.37599e-07 3.01198e-07 2.11203e-07" />
                              <joint name="right_finger1_joint1" pos="0 0 0" axis="0 1 0" range="0.0368 1.6125" actuatorfrcrange="-0.4452 0.4452" />
                              <geom type="mesh" contype="0" conaffinity="0" group="1" density="0" rgba="0.7 0.7 0.7 1" mesh="right_finger1_link1" />
                              <geom type="mesh" rgba="0.7 0.7 0.7 1" mesh="right_finger1_link1" contype="0" conaffinity="0" />
                              <body name="right_finger1_link2" pos="-0.0047549 -0.0060191 0.014132" quat="0.616955 -0.0855901 -0.290851 0.726255">
                                <inertial pos="0.0011196 -1.2405e-05 0.015663" quat="0.815906 0.0024483 -0.00462559 0.57816" mass="0.0248" diaginertia="2.81725e-06 2.75299e-06 6.79766e-07" />
                                <joint name="right_finger1_joint2" pos="0 0 0" axis="0 -1 0" range="-0.1576 0.9312" actuatorfrcrange="-0.4259 0.4259" />
                                <geom type="mesh" contype="0" conaffinity="0" group="1" density="0" rgba="0.9 0.8 0.6 1" mesh="right_finger1_link2" />
                                <geom type="mesh" rgba="0.9 0.8 0.6 1" mesh="right_finger1_link2" contype="2" conaffinity="2" />
                                <body name="right_finger1_link3" pos="0.00018873 -0.0009916 0.034664" quat="0.577852 0.0212383 -0.0150031 -0.815727">
                                  <inertial pos="-0.0011235 -1.579e-05 0.013056" quat="0.999951 0 0.00989566 0" mass="0.0165" diaginertia="1.4604e-06 1.42e-06 4.49604e-07" />
                                  <joint name="right_finger1_joint3" pos="0 0 0" axis="0 1 0" range="-0.4638 1.5607" actuatorfrcrange="-0.1888 0.1888" />
                                  <geom type="mesh" contype="0" conaffinity="0" group="1" density="0" rgba="0.6 0.8 0.9 1" mesh="right_finger1_link3" />
                                  <geom type="mesh" rgba="0.6 0.8 0.9 1" mesh="right_finger1_link3" contype="1" conaffinity="1" />
                                  <body name="right_finger1_link4" pos="0 -0.00025 0.0295">
                                    <inertial pos="-0.00160983 0.000234366 0.0113487" quat="0.705453 -0.0487835 -0.0489426 0.705379" mass="0.0206" diaginertia="2.60023e-06 2.58038e-06 7.59852e-07" />
                                    <joint name="right_finger1_joint4" pos="0 0 0" axis="0 1 0" range="-0.4829 1.5451" actuatorfrcrange="-0.1468 0.1468" />
                                    <geom type="mesh" contype="0" conaffinity="0" group="1" density="0" rgba="0.6 0.8 0.9 1" mesh="right_finger1_link4" />
                                    <geom type="mesh" rgba="0.6 0.8 0.9 1" mesh="right_finger1_link4" contype="1" conaffinity="1" />
                                    <geom pos="-0.0011048 0.00023218 0.0283" type="mesh" contype="0" conaffinity="0" group="1" density="0" rgba="0.6 0.8 0.9 1" mesh="right_finger1_tip_link" />
                                    <geom pos="-0.0011048 0.00023218 0.0283" type="mesh" rgba="0.6 0.8 0.9 1" mesh="right_finger1_tip_link" contype="1" conaffinity="1" />
                                  </body>
                                </body>
                              </body>
                            </body>
                            <body name="right_finger2_link1" pos="-0.0058701 0.029434 0.091917" quat="0.991689 -0.0588295 -0.0292755 -0.110614">
                              <inertial pos="-0.0013291 -3.2911e-08 0.00031987" quat="0.92388 0 0.382683 0" mass="0.0032" diaginertia="1.1e-07 7e-08 5e-08" />
                              <joint name="right_finger2_joint1" pos="0 0 0" axis="0 1 0" range="-0.1611 1.5588" actuatorfrcrange="-0.6188 0.6188" />
                              <geom type="mesh" contype="0" conaffinity="0" group="1" density="0" rgba="0.7 0.7 0.7 1" mesh="right_finger2_link1" />
                              <geom type="mesh" rgba="0.7 0.7 0.7 1" mesh="right_finger2_link1" contype="0" conaffinity="0" />
                              <body name="right_finger2_link2" pos="0.0022 0 0.004">
                                <inertial pos="-0.0061577 -4.1189e-07 0.020911" quat="0.70703 0.0104245 0.0104245 0.70703" mass="0.033" diaginertia="6.34e-06 6.31472e-06 8.85281e-07" />
                                <joint name="right_finger2_joint2" pos="0 0 0" axis="-1 0 0" range="-0.4044 0.3054" actuatorfrcrange="-0.1822 0.1822" />
                                <geom type="mesh" contype="0" conaffinity="0" group="1" density="0" rgba="0.9 0.8 0.6 1" mesh="right_finger2_link2" />
                                <geom type="mesh" rgba="0.9 0.8 0.6 1" mesh="right_finger2_link2" contype="2" conaffinity="2" />
                                <body name="right_finger2_link3" pos="-0.0047503 0 0.043618" quat="1 0 0 -0.000134305">
                                  <inertial pos="-0.0011668 4.1873e-06 0.026893" quat="0.999892 0 -0.0146884 0" mass="0.0165" diaginertia="1.47088e-06 1.44e-06 4.49118e-07" />
                                  <joint name="right_finger2_joint3" pos="0 0 0" axis="0 1 0" range="-0.4714 1.5504" actuatorfrcrange="-0.2251 0.2251" />
                                  <geom type="mesh" contype="0" conaffinity="0" group="1" density="0" rgba="0.6 0.8 0.9 1" mesh="right_finger2_link3" />
                                  <geom type="mesh" rgba="0.6 0.8 0.9 1" mesh="right_finger2_link3" contype="1" conaffinity="1" />
                                  <body name="right_finger2_link4" pos="0 0 0.0295">
                                    <inertial pos="-0.000766056 -0.000179751 0.00770944" quat="0.998354 0.0103509 -0.0508894 0.0243386" mass="0.01718" diaginertia="1.58547e-06 1.49202e-06 4.21685e-07" />
                                    <joint name="right_finger2_joint4" pos="0 0 0" axis="0 1 0" range="-0.4644 1.5753" actuatorfrcrange="-0.217 0.217" />
                                    <geom type="mesh" contype="0" conaffinity="0" group="1" density="0" rgba="0.6 0.8 0.9 1" mesh="right_finger2_link4" />
                                    <geom type="mesh" rgba="0.6 0.8 0.9 1" mesh="right_finger2_link4" contype="1" conaffinity="1" />
                                    <geom pos="-0.00105 0 0.0274" type="mesh" contype="0" conaffinity="0" group="1" density="0" rgba="0.6 0.8 0.9 1" mesh="right_finger2_tip_link" />
                                    <geom pos="-0.00105 0 0.0274" type="mesh" rgba="0.6 0.8 0.9 1" mesh="right_finger2_tip_link" contype="1" conaffinity="1" />
                                  </body>
                                </body>
                              </body>
                            </body>
                            <body name="right_finger3_link1" pos="-0.01046 0.0074615 0.089544" quat="0.999048 -1.26848e-05 -0.0436192 0.000290547">
                              <inertial pos="-0.0013291 3.4987e-09 0.00031994" quat="0.92388 0 0.382683 0" mass="0.0032" diaginertia="1.1e-07 7e-08 5e-08" />
                              <joint name="right_finger3_joint1" pos="0 0 0" axis="0 1 0" range="-0.1719 1.5496" actuatorfrcrange="-0.6494 0.6494" />
                              <geom type="mesh" contype="0" conaffinity="0" group="1" density="0" rgba="0.7 0.7 0.7 1" mesh="right_finger3_link1" />
                              <geom type="mesh" rgba="0.7 0.7 0.7 1" mesh="right_finger3_link1" contype="0" conaffinity="0" />
                              <body name="right_finger3_link2" pos="0.0022 0 0.004">
                                <inertial pos="-0.0061576 -4.1651e-07 0.020911" quat="0.70703 0.0104245 0.0104245 0.70703" mass="0.033" diaginertia="6.34e-06 6.31472e-06 8.85281e-07" />
                                <joint name="right_finger3_joint2" pos="0 0 0" axis="-1 0 0" range="-0.4014 0.2996" actuatorfrcrange="-0.1827 0.1827" />
                                <geom type="mesh" contype="0" conaffinity="0" group="1" density="0" rgba="0.9 0.8 0.6 1" mesh="right_finger3_link2" />
                                <geom type="mesh" rgba="0.9 0.8 0.6 1" mesh="right_finger3_link2" contype="2" conaffinity="2" />
                                <body name="right_finger3_link3" pos="-0.00475 0 0.043618" quat="1 0 0 -0.000134305">
                                  <inertial pos="-0.0011214 4.331e-06 0.015763" quat="0.999892 0 -0.0146884 0" mass="0.0165" diaginertia="1.47088e-06 1.44e-06 4.49118e-07" />
                                  <joint name="right_finger3_joint3" pos="0 0 0" axis="0 1 0" range="-0.4632 1.5613" actuatorfrcrange="-0.2078 0.2078" />
                                  <geom type="mesh" contype="0" conaffinity="0" group="1" density="0" rgba="0.6 0.8 0.9 1" mesh="right_finger3_link3" />
                                  <geom type="mesh" rgba="0.6 0.8 0.9 1" mesh="right_finger3_link3" contype="1" conaffinity="1" />
                                  <body name="right_finger3_link4" pos="0 0 0.0295">
                                    <inertial pos="-0.000766442 -0.000180017 0.00770944" quat="0.998352 0.0103722 -0.0509199 0.0243491" mass="0.01718" diaginertia="1.5855e-06 1.49202e-06 4.21669e-07" />
                                    <joint name="right_finger3_joint4" pos="0 0 0" axis="0 1 0" range="-0.4697 1.5702" actuatorfrcrange="-0.2018 0.2018" />
                                    <geom type="mesh" contype="0" conaffinity="0" group="1" density="0" rgba="0.6 0.8 0.9 1" mesh="right_finger3_link4" />
                                    <geom type="mesh" rgba="0.6 0.8 0.9 1" mesh="right_finger3_link4" contype="1" conaffinity="1" />
                                    <geom pos="-0.0010491 0 0.0267" type="mesh" contype="0" conaffinity="0" group="1" density="0" rgba="0.6 0.8 0.9 1" mesh="right_finger3_tip_link" />
                                    <geom pos="-0.0010491 0 0.0267" type="mesh" rgba="0.6 0.8 0.9 1" mesh="right_finger3_tip_link" contype="1" conaffinity="1" />
                                  </body>
                                </body>
                              </body>
                            </body>
                            <body name="right_finger4_link1" pos="-0.0076649 -0.013712 0.084429" quat="0.997789 0.0461019 -0.0405884 0.0254002">
                              <inertial pos="-0.0013291 1.0048e-08 0.00031995" quat="0.92388 0 0.382683 0" mass="0.0032" diaginertia="1.1e-07 7e-08 5e-08" />
                              <joint name="right_finger4_joint1" pos="0 0 0" axis="0 1 0" range="-0.1601 1.5534" actuatorfrcrange="-0.6389 0.6389" />
                              <geom type="mesh" contype="0" conaffinity="0" group="1" density="0" rgba="0.7 0.7 0.7 1" mesh="right_finger4_link1" />
                              <geom type="mesh" rgba="0.7 0.7 0.7 1" mesh="right_finger4_link1" contype="0" conaffinity="0" />
                              <body name="right_finger4_link2" pos="0.0022 0 0.004">
                                <inertial pos="-0.0061576 -4.1601e-07 0.020911" quat="0.70703 0.0104245 0.0104245 0.70703" mass="0.033" diaginertia="6.34e-06 6.31472e-06 8.85281e-07" />
                                <joint name="right_finger4_joint2" pos="0 0 0" axis="-1 0 0" range="-0.4134 0.3161" actuatorfrcrange="-0.1832 0.1832" />
                                <geom type="mesh" contype="0" conaffinity="0" group="1" density="0" rgba="0.9 0.8 0.6 1" mesh="right_finger4_link2" />
                                <geom type="mesh" rgba="0.9 0.8 0.6 1" mesh="right_finger4_link2" contype="2" conaffinity="2" />
                                <body name="right_finger4_link3" pos="-0.00475 0 0.043618" quat="1 0 0 -0.000134305">
                                  <inertial pos="-0.0011214 4.3494e-06 0.015763" quat="0.999892 0 -0.0146884 0" mass="0.0165" diaginertia="1.47088e-06 1.44e-06 4.49118e-07" />
                                  <joint name="right_finger4_joint3" pos="0 0 0" axis="0 1 0" range="-0.4782 1.5448" actuatorfrcrange="-0.2249 0.2249" />
                                  <geom type="mesh" contype="0" conaffinity="0" group="1" density="0" rgba="0.6 0.8 0.9 1" mesh="right_finger4_link3" />
                                  <geom type="mesh" rgba="0.6 0.8 0.9 1" mesh="right_finger4_link3" contype="1" conaffinity="1" />
                                  <body name="right_finger4_link4" pos="0 0 0.0295">
                                    <inertial pos="-0.000766431 -0.000180689 0.00770952" quat="0.998349 0.0104237 -0.0509196 0.0244494" mass="0.01718" diaginertia="1.58554e-06 1.49205e-06 4.21684e-07" />
                                    <joint name="right_finger4_joint4" pos="0 0 0" axis="0 1 0" range="-0.4825 1.555" actuatorfrcrange="-0.2044 0.2044" />
                                    <geom type="mesh" contype="0" conaffinity="0" group="1" density="0" rgba="0.6 0.8 0.9 1" mesh="right_finger4_link4" />
                                    <geom type="mesh" rgba="0.6 0.8 0.9 1" mesh="right_finger4_link4" contype="1" conaffinity="1" />
                                    <geom pos="-0.0010528 0 0.0267" type="mesh" contype="0" conaffinity="0" group="1" density="0" rgba="0.6 0.8 0.9 1" mesh="right_finger4_tip_link" />
                                    <geom pos="-0.0010528 0 0.0267" type="mesh" rgba="0.6 0.8 0.9 1" mesh="right_finger4_tip_link" contype="1" conaffinity="1" />
                                  </body>
                                </body>
                              </body>
                            </body>
                            <body name="right_finger5_link1" pos="-0.0022687 -0.034001 0.074281" quat="0.99087 0.0993154 -0.0383256 0.0827347">
                              <inertial pos="-0.0013291 1.7235e-08 0.00031997" quat="0.92388 0 0.382683 0" mass="0.0032" diaginertia="1.1e-07 7e-08 5e-08" />
                              <joint name="right_finger5_joint1" pos="0 0 0" axis="0 1 0" range="-0.1674 1.5539" actuatorfrcrange="-0.6441 0.6441" />
                              <geom type="mesh" contype="0" conaffinity="0" group="1" density="0" rgba="0.7 0.7 0.7 1" mesh="right_finger5_link1" />
                              <geom type="mesh" rgba="0.7 0.7 0.7 1" mesh="right_finger5_link1" contype="0" conaffinity="0" />
                              <body name="right_finger5_link2" pos="0.0022 0 0.004">
                                <inertial pos="-0.0061576 -4.1475e-07 0.020911" quat="0.70703 0.0104245 0.0104245 0.70703" mass="0.033" diaginertia="6.34e-06 6.31472e-06 8.85281e-07" />
                                <joint name="right_finger5_joint2" pos="0 0 0" axis="-1 0 0" range="-0.4203 0.2931" actuatorfrcrange="-0.1798 0.1798" />
                                <geom type="mesh" contype="0" conaffinity="0" group="1" density="0" rgba="0.9 0.8 0.6 1" mesh="right_finger5_link2" />
                                <geom type="mesh" rgba="0.9 0.8 0.6 1" mesh="right_finger5_link2" contype="2" conaffinity="2" />
                                <body name="right_finger5_link3" pos="-0.00475 0 0.043618" quat="1 0 0 -0.000134305">
                                  <inertial pos="-0.0011214 4.3703e-06 0.015763" quat="0.999892 0 -0.0146884 0" mass="0.0165" diaginertia="1.47088e-06 1.44e-06 4.49118e-07" />
                                  <joint name="right_finger5_joint3" pos="0 0 0" axis="0 1 0" range="-0.4804 1.542" actuatorfrcrange="-0.2384 0.2384" />
                                  <geom type="mesh" contype="0" conaffinity="0" group="1" density="0" rgba="0.6 0.8 0.9 1" mesh="right_finger5_link3" />
                                  <geom type="mesh" rgba="0.6 0.8 0.9 1" mesh="right_finger5_link3" contype="1" conaffinity="1" />
                                  <body name="right_finger5_link4" pos="0 0 0.0295">
                                    <inertial pos="-0.00076855 -0.000179174 0.00770942" quat="0.998351 0.0103138 -0.0510722 0.024077" mass="0.01718" diaginertia="1.58554e-06 1.49197e-06 4.21535e-07" />
                                    <joint name="right_finger5_joint4" pos="0 0 0" axis="0 1 0" range="-0.4705 1.5709" actuatorfrcrange="-0.1866 0.1866" />
                                    <geom type="mesh" contype="0" conaffinity="0" group="1" density="0" rgba="0.6 0.8 0.9 1" mesh="right_finger5_link4" />
                                    <geom type="mesh" rgba="0.6 0.8 0.9 1" mesh="right_finger5_link4" contype="1" conaffinity="1" />
                                    <geom pos="-0.0010446 1.1308e-05 0.0267" type="mesh" contype="0" conaffinity="0" group="1" density="0" rgba="0.6 0.8 0.9 1" mesh="right_finger5_tip_link" />
                                    <geom pos="-0.0010446 1.1308e-05 0.0267" type="mesh" rgba="0.6 0.8 0.9 1" mesh="right_finger5_tip_link" contype="1" conaffinity="1" />
                                  </body>
                                </body>
                              </body>
                            </body>
                          </body>
                        </body>
                      </body>
                    </body>
                  </body>
                </body>
              </body>
            </body>
            <body name="neck_yaw_link" pos="0.01443 0.35455 0.023" quat="2.81105e-14 2.25872e-14 0.707107 -0.707107">
              <joint axis="0 0 1" name="neck_yaw_joint" type="hinge" range="-3.1415926535897487 3.1415926535898375" armature="0.3" damping="1.5" />
              <inertial pos="3.01692e-05 -2.95874e-08 -0.025262" mass="9.23497e-05" fullinertia="2.57971e-08 3.72339e-08 3.71365e-08 3.86016e-14 1.93175e-10 5.77657e-14" />
              <geom type="mesh" class="visual" pos="3.01692e-05 -2.95874e-08 -0.025262" quat="1.63214e-13 1 -9.78881e-14 9.20295e-14" mesh="neck_yaw_link_visual" material="neck_yaw_link_visual_material" />
              <geom type="mesh" class="collision" pos="3.01692e-05 -2.95874e-08 -0.025262" quat="1.63214e-13 1 -9.78881e-14 9.20295e-14" mesh="neck_yaw_link_collision" material="neck_yaw_link_collision_material" />
              <body name="neck_roll_link" pos="-0.0303 2.17579e-15 -0.0255" quat="3.97223e-15 0.707107 3.88578e-15 0.707107">
                <joint axis="0 0 1" name="neck_roll_joint" type="hinge" range="-0.7853981633974394 0.7853981633974572" armature="0.3" damping="1.5" />
                <inertial pos="-0.0430653 -0.000214234 0.0303228" mass="0.000107143" fullinertia="5.21547e-08 5.03411e-08 5.2811e-08 -2.41301e-10 4.00021e-10 -6.60546e-13" />
                <geom type="mesh" class="visual" pos="-0.0430653 -0.000214234 0.0303228" quat="0.707107 -1.80655e-13 -0.707107 -4.23767e-14" mesh="neck_roll_link_visual" material="neck_roll_link_visual_material" />
                <geom type="mesh" class="collision" pos="-0.0430653 -0.000214234 0.0303228" quat="0.707107 -1.80655e-13 -0.707107 -4.23767e-14" mesh="neck_roll_link_collision" material="neck_roll_link_collision_material" />
                <body name="neck_pitch_link" pos="-0.047 0.0288 0.0303" quat="0.707107 0.707107 6.66134e-16 8.9927e-16">
                  <joint axis="0 0 1" name="neck_pitch_joint" type="hinge" range="-0.34906585039886145 0.08726646259972091" armature="0.3" damping="1.5" />
                  <inertial pos="-0.0597711 0.0161645 0.0287467" mass="0.645759" fullinertia="0.00323048 0.00321103 0.00372135 -0.000419023 2.92028e-06 -2.89743e-07" />
                  <geom type="mesh" class="visual" pos="-0.0597711 0.0161645 0.0287467" quat="0.5 -0.5 -0.5 0.5" mesh="neck_pitch_link_visual" material="neck_pitch_link_visual_material" />
                  <geom type="mesh" class="collision" pos="-0.0597711 0.0161645 0.0287467" quat="0.5 -0.5 -0.5 0.5" mesh="neck_pitch_link_collision" material="neck_pitch_link_collision_material" />
                </body>
              </body>
            </body>
          </body>
        </body>
      </body>
    </body>
  </worldbody>
  <asset>
    <mesh file="merged/left_wrist_pitch_link_collision.stl" />
    <mesh file="merged/waist_yaw_link_collision.stl" />
    <mesh file="merged/right_shoulder_yaw_link_collision.stl" />
    <mesh file="merged/right_wrist_yaw_link_visual.stl" />
    <mesh file="merged/left_wrist_roll_link_visual.stl" />
    <mesh file="merged/neck_yaw_link_visual.stl" />
    <mesh file="merged/right_shoulder_roll_link_collision.stl" />
    <mesh file="merged/left_elbow_pitch_link_collision.stl" />
    <mesh file="merged/chest_link_visual.stl" />
    <mesh file="merged/left_shoulder_pitch_link_collision.stl" />
    <mesh file="merged/right_wrist_yaw_link_collision.stl" />
    <mesh file="merged/waist_right_passive_link_visual.stl" />
    <mesh file="merged/waist_left_link_collision.stl" />
    <mesh file="merged/right_wrist_ptich_link_collision.stl" />
    <mesh file="merged/waist_left_passive_link_collision.stl" />
    <mesh file="merged/waist_right_link_visual.stl" />
    <mesh file="merged/left_shoulder_yaw_link_visual.stl" />
    <mesh file="merged/waist_left_passive_link_visual.stl" />
    <mesh file="merged/left_shoulder_pitch_link_visual.stl" />
    <mesh file="merged/left_elbow_pitch_link_visual.stl" />
    <mesh file="merged/left_shoulder_yaw_link_collision.stl" />
    <mesh file="merged/right_shoulder_yaw_link_visual.stl" />
    <mesh file="merged/right_wrist_ptich_link_visual.stl" />
    <mesh file="merged/waist_yaw_link_visual.stl" />
    <mesh file="merged/left_wrist_yaw_link_visual.stl" />
    <mesh file="merged/left_wrist_pitch_link_visual.stl" />
    <mesh file="merged/right_elbow_pitch_link_collision.stl" />
    <mesh file="merged/waist_right_passive_link_collision.stl" />
    <mesh file="merged/left_wrist_yaw_link_collision.stl" />
    <mesh file="merged/neck_pitch_link_collision.stl" />
    <mesh file="merged/right_shoulder_roll_link_visual.stl" />
    <mesh file="merged/right_shoulder_pitch_link_visual.stl" />
    <mesh file="merged/waist_left_link_visual.stl" />
    <mesh file="merged/waist_roll_link_visual.stl" />
    <mesh file="merged/neck_roll_link_visual.stl" />
    <mesh file="merged/neck_roll_link_collision.stl" />
    <mesh file="merged/left_shoulder_roll_link_visual.stl" />
    <mesh file="merged/right_wrist_roll_link_visual.stl" />
    <mesh file="merged/body_base_link_collision.stl" />
    <mesh file="merged/right_shoulder_pitch_link_collision.stl" />
    <mesh file="merged/neck_pitch_link_visual.stl" />
    <mesh file="merged/waist_right_link_collision.stl" />
    <mesh file="merged/body_base_link_visual.stl" />
    <mesh file="merged/waist_roll_link_collision.stl" />
    <mesh file="merged/chest_link_collision.stl" />
    <mesh file="merged/left_wrist_roll_link_collision.stl" />
    <mesh file="merged/right_elbow_pitch_link_visual.stl" />
    <mesh file="merged/neck_yaw_link_collision.stl" />
    <mesh file="merged/left_shoulder_roll_link_collision.stl" />
    <mesh file="merged/right_wrist_roll_link_collision.stl" />
    <material name="body_base_link_visual_material" rgba="0.623029 0.814339 0.929126 1" />
    <material name="body_base_link_collision_material" rgba="0.623029 0.814339 0.929126 1" />
    <material name="waist_yaw_link_visual_material" rgba="0.62997 0.641781 0.667579 1" />
    <material name="waist_yaw_link_collision_material" rgba="0.62997 0.641781 0.667579 1" />
    <material name="waist_roll_link_visual_material" rgba="0.81186 0.895376 0.942702 1" />
    <material name="waist_roll_link_collision_material" rgba="0.81186 0.895376 0.942702 1" />
    <material name="chest_link_visual_material" rgba="0.775413 0.837045 0.865614 1" />
    <material name="chest_link_collision_material" rgba="0.775413 0.837045 0.865614 1" />
    <material name="waist_left_link_visual_material" rgba="0.651753 0.797067 0.884255 1" />
    <material name="waist_left_link_collision_material" rgba="0.651753 0.797067 0.884255 1" />
    <material name="waist_left_passive_link_visual_material" rgba="0.410396 0.459373 0.566349 1" />
    <material name="waist_left_passive_link_collision_material" rgba="0.410396 0.459373 0.566349 1" />
    <material name="waist_right_link_visual_material" rgba="0.651753 0.797067 0.884255 1" />
    <material name="waist_right_link_collision_material" rgba="0.651753 0.797067 0.884255 1" />
    <material name="waist_right_passive_link_visual_material" rgba="0.410396 0.459373 0.566349 1" />
    <material name="waist_right_passive_link_collision_material" rgba="0.410396 0.459373 0.566349 1" />
    <material name="left_shoulder_pitch_link_visual_material" rgba="0.661727 0.814348 0.901578 1" />
    <material name="left_shoulder_pitch_link_collision_material" rgba="0.661727 0.814348 0.901578 1" />
    <material name="left_shoulder_roll_link_visual_material" rgba="0.495831 0.510254 0.526236 1" />
    <material name="left_shoulder_roll_link_collision_material" rgba="0.495831 0.510254 0.526236 1" />
    <material name="left_shoulder_yaw_link_visual_material" rgba="0.534608 0.588362 0.619697 1" />
    <material name="left_shoulder_yaw_link_collision_material" rgba="0.534608 0.588362 0.619697 1" />
    <material name="left_elbow_pitch_link_visual_material" rgba="0.540973 0.537254 0.515031 1" />
    <material name="left_elbow_pitch_link_collision_material" rgba="0.540973 0.537254 0.515031 1" />
    <material name="left_wrist_roll_link_visual_material" rgba="0.616041 0.753599 0.806876 1" />
    <material name="left_wrist_roll_link_collision_material" rgba="0.616041 0.753599 0.806876 1" />
    <material name="left_wrist_pitch_link_visual_material" rgba="0.637078 0.780124 0.849341 1" />
    <material name="left_wrist_pitch_link_collision_material" rgba="0.637078 0.780124 0.849341 1" />
    <material name="left_wrist_yaw_link_visual_material" rgba="0.594174 0.694485 0.754671 1" />
    <material name="left_wrist_yaw_link_collision_material" rgba="0.594174 0.694485 0.754671 1" />
    <material name="right_shoulder_pitch_link_visual_material" rgba="0.666158 0.787435 0.786963 1" />
    <material name="right_shoulder_pitch_link_collision_material" rgba="0.666158 0.787435 0.786963 1" />
    <material name="right_shoulder_roll_link_visual_material" rgba="0.524464 0.533979 0.539688 1" />
    <material name="right_shoulder_roll_link_collision_material" rgba="0.524464 0.533979 0.539688 1" />
    <material name="right_shoulder_yaw_link_visual_material" rgba="0.579661 0.60817 0.621792 1" />
    <material name="right_shoulder_yaw_link_collision_material" rgba="0.579661 0.60817 0.621792 1" />
    <material name="right_elbow_pitch_link_visual_material" rgba="0.588878 0.529825 0.457356 1" />
    <material name="right_elbow_pitch_link_collision_material" rgba="0.588878 0.529825 0.457356 1" />
    <material name="right_wrist_roll_link_visual_material" rgba="0.650084 0.792364 0.881286 1" />
    <material name="right_wrist_roll_link_collision_material" rgba="0.650084 0.792364 0.881286 1" />
    <material name="right_wrist_ptich_link_visual_material" rgba="0.698304 0.762657 0.745079 1" />
    <material name="right_wrist_ptich_link_collision_material" rgba="0.698304 0.762657 0.745079 1" />
    <material name="right_wrist_yaw_link_visual_material" rgba="0.594174 0.694485 0.754671 1" />
    <material name="right_wrist_yaw_link_collision_material" rgba="0.594174 0.694485 0.754671 1" />
    <material name="neck_yaw_link_visual_material" rgba="0.470469 0.628627 0.781159 1" />
    <material name="neck_yaw_link_collision_material" rgba="0.470469 0.628627 0.781159 1" />
    <material name="neck_roll_link_visual_material" rgba="0.604479 0.726595 0.787909 1" />
    <material name="neck_roll_link_collision_material" rgba="0.604479 0.726595 0.787909 1" />
    <material name="neck_pitch_link_visual_material" rgba="0.649683 0.685003 0.686591 1" />
    <material name="neck_pitch_link_collision_material" rgba="0.649683 0.685003 0.686591 1" />
    <mesh name="left_palm_link" content_type="model/stl" file="../wuji-hand-description/meshes/left/left_palm_link.STL" />
    <mesh name="left_finger1_link1" content_type="model/stl" file="../wuji-hand-description/meshes/left/left_finger1_link1.STL" />
    <mesh name="left_finger1_link2" content_type="model/stl" file="../wuji-hand-description/meshes/left/left_finger1_link2.STL" />
    <mesh name="left_finger1_link3" content_type="model/stl" file="../wuji-hand-description/meshes/left/left_finger1_link3.STL" />
    <mesh name="left_finger1_link4" content_type="model/stl" file="../wuji-hand-description/meshes/left/left_finger1_link4.STL" />
    <mesh name="left_finger1_tip_link" content_type="model/stl" file="../wuji-hand-description/meshes/left/left_finger1_tip_link.STL" />
    <mesh name="left_finger2_link1" content_type="model/stl" file="../wuji-hand-description/meshes/left/left_finger2_link1.STL" />
    <mesh name="left_finger2_link2" content_type="model/stl" file="../wuji-hand-description/meshes/left/left_finger2_link2.STL" />
    <mesh name="left_finger2_link3" content_type="model/stl" file="../wuji-hand-description/meshes/left/left_finger2_link3.STL" />
    <mesh name="left_finger2_link4" content_type="model/stl" file="../wuji-hand-description/meshes/left/left_finger2_link4.STL" />
    <mesh name="left_finger2_tip_link" content_type="model/stl" file="../wuji-hand-description/meshes/left/left_finger2_tip_link.STL" />
    <mesh name="left_finger3_link1" content_type="model/stl" file="../wuji-hand-description/meshes/left/left_finger3_link1.STL" />
    <mesh name="left_finger3_link2" content_type="model/stl" file="../wuji-hand-description/meshes/left/left_finger3_link2.STL" />
    <mesh name="left_finger3_link3" content_type="model/stl" file="../wuji-hand-description/meshes/left/left_finger3_link3.STL" />
    <mesh name="left_finger3_link4" content_type="model/stl" file="../wuji-hand-description/meshes/left/left_finger3_link4.STL" />
    <mesh name="left_finger3_tip_link" content_type="model/stl" file="../wuji-hand-description/meshes/left/left_finger3_tip_link.STL" />
    <mesh name="left_finger4_link1" content_type="model/stl" file="../wuji-hand-description/meshes/left/left_finger4_link1.STL" />
    <mesh name="left_finger4_link2" content_type="model/stl" file="../wuji-hand-description/meshes/left/left_finger4_link2.STL" />
    <mesh name="left_finger4_link3" content_type="model/stl" file="../wuji-hand-description/meshes/left/left_finger4_link3.STL" />
    <mesh name="left_finger4_link4" content_type="model/stl" file="../wuji-hand-description/meshes/left/left_finger4_link4.STL" />
    <mesh name="left_finger4_tip_link" content_type="model/stl" file="../wuji-hand-description/meshes/left/left_finger4_tip_link.STL" />
    <mesh name="left_finger5_link1" content_type="model/stl" file="../wuji-hand-description/meshes/left/left_finger5_link1.STL" />
    <mesh name="left_finger5_link2" content_type="model/stl" file="../wuji-hand-description/meshes/left/left_finger5_link2.STL" />
    <mesh name="left_finger5_link3" content_type="model/stl" file="../wuji-hand-description/meshes/left/left_finger5_link3.STL" />
    <mesh name="left_finger5_link4" content_type="model/stl" file="../wuji-hand-description/meshes/left/left_finger5_link4.STL" />
    <mesh name="left_finger5_tip_link" content_type="model/stl" file="../wuji-hand-description/meshes/left/left_finger5_tip_link.STL" />
    <mesh name="right_palm_link" content_type="model/stl" file="../wuji-hand-description/meshes/right/right_palm_link.STL" />
    <mesh name="right_finger1_link1" content_type="model/stl" file="../wuji-hand-description/meshes/right/right_finger1_link1.STL" />
    <mesh name="right_finger1_link2" content_type="model/stl" file="../wuji-hand-description/meshes/right/right_finger1_link2.STL" />
    <mesh name="right_finger1_link3" content_type="model/stl" file="../wuji-hand-description/meshes/right/right_finger1_link3.STL" />
    <mesh name="right_finger1_link4" content_type="model/stl" file="../wuji-hand-description/meshes/right/right_finger1_link4.STL" />
    <mesh name="right_finger1_tip_link" content_type="model/stl" file="../wuji-hand-description/meshes/right/right_finger1_tip_link.STL" />
    <mesh name="right_finger2_link1" content_type="model/stl" file="../wuji-hand-description/meshes/right/right_finger2_link1.STL" />
    <mesh name="right_finger2_link2" content_type="model/stl" file="../wuji-hand-description/meshes/right/right_finger2_link2.STL" />
    <mesh name="right_finger2_link3" content_type="model/stl" file="../wuji-hand-description/meshes/right/right_finger2_link3.STL" />
    <mesh name="right_finger2_link4" content_type="model/stl" file="../wuji-hand-description/meshes/right/right_finger2_link4.STL" />
    <mesh name="right_finger2_tip_link" content_type="model/stl" file="../wuji-hand-description/meshes/right/right_finger2_tip_link.STL" />
    <mesh name="right_finger3_link1" content_type="model/stl" file="../wuji-hand-description/meshes/right/right_finger3_link1.STL" />
    <mesh name="right_finger3_link2" content_type="model/stl" file="../wuji-hand-description/meshes/right/right_finger3_link2.STL" />
    <mesh name="right_finger3_link3" content_type="model/stl" file="../wuji-hand-description/meshes/right/right_finger3_link3.STL" />
    <mesh name="right_finger3_link4" content_type="model/stl" file="../wuji-hand-description/meshes/right/right_finger3_link4.STL" />
    <mesh name="right_finger3_tip_link" content_type="model/stl" file="../wuji-hand-description/meshes/right/right_finger3_tip_link.STL" />
    <mesh name="right_finger4_link1" content_type="model/stl" file="../wuji-hand-description/meshes/right/right_finger4_link1.STL" />
    <mesh name="right_finger4_link2" content_type="model/stl" file="../wuji-hand-description/meshes/right/right_finger4_link2.STL" />
    <mesh name="right_finger4_link3" content_type="model/stl" file="../wuji-hand-description/meshes/right/right_finger4_link3.STL" />
    <mesh name="right_finger4_link4" content_type="model/stl" file="../wuji-hand-description/meshes/right/right_finger4_link4.STL" />
    <mesh name="right_finger4_tip_link" content_type="model/stl" file="../wuji-hand-description/meshes/right/right_finger4_tip_link.STL" />
    <mesh name="right_finger5_link1" content_type="model/stl" file="../wuji-hand-description/meshes/right/right_finger5_link1.STL" />
    <mesh name="right_finger5_link2" content_type="model/stl" file="../wuji-hand-description/meshes/right/right_finger5_link2.STL" />
    <mesh name="right_finger5_link3" content_type="model/stl" file="../wuji-hand-description/meshes/right/right_finger5_link3.STL" />
    <mesh name="right_finger5_link4" content_type="model/stl" file="../wuji-hand-description/meshes/right/right_finger5_link4.STL" />
    <mesh name="right_finger5_tip_link" content_type="model/stl" file="../wuji-hand-description/meshes/right/right_finger5_tip_link.STL" />
  </asset>
  <actuator>
    <position class="mjcf" name="waist_yaw_joint" joint="waist_yaw_joint" forcerange="-96 96" inheritrange="1" />
    <position class="mjcf" name="waist_left_joint" joint="waist_left_joint" forcerange="-96 96" inheritrange="1" />
    <position class="mjcf" name="waist_right_joint" joint="waist_right_joint" forcerange="-96 96" inheritrange="1" />
    <position class="mjcf" name="left_shoulder_pitch_joint" joint="left_shoulder_pitch_joint" forcerange="-70 70" inheritrange="1" />
    <position class="mjcf" name="left_shoulder_roll_joint" joint="left_shoulder_roll_joint" forcerange="-70 70" inheritrange="1" />
    <position class="mjcf" name="left_shoulder_yaw_joint" joint="left_shoulder_yaw_joint" forcerange="-23 23" inheritrange="1" />
    <position class="mjcf" name="left_elbow_pitch_joint" joint="left_elbow_pitch_joint" forcerange="-23 23" inheritrange="1" />
    <position class="mjcf" name="left_wrist_roll_joint" joint="left_wrist_roll_joint" forcerange="-23 23" inheritrange="1" />
    <position class="mjcf" name="left_wrist_pitch_joint" joint="left_wrist_pitch_joint" forcerange="-4.8 4.8" inheritrange="1" />
    <position class="mjcf" name="left_wrist_yaw_joint" joint="left_wrist_yaw_joint" forcerange="-4.8 4.8" inheritrange="1" />
    <position class="mjcf" name="right_shoulder_pitch_joint" joint="right_shoulder_pitch_joint" forcerange="-70 70" inheritrange="1" />
    <position class="mjcf" name="right_shoulder_roll_joint" joint="right_shoulder_roll_joint" forcerange="-70 70" inheritrange="1" />
    <position class="mjcf" name="right_shoulder_yaw_joint" joint="right_shoulder_yaw_joint" forcerange="-23 23" inheritrange="1" />
    <position class="mjcf" name="right_elbow_pitch_joint" joint="right_elbow_pitch_joint" forcerange="-23 23" inheritrange="1" />
    <position class="mjcf" name="right_wrist_roll_joint" joint="right_wrist_roll_joint" forcerange="-23 23" inheritrange="1" />
    <position class="mjcf" name="right_wrist_pitch_joint" joint="right_wrist_pitch_joint" forcerange="-4.8 4.8" inheritrange="1" />
    <position class="mjcf" name="right_wrist_yaw_joint" joint="right_wrist_yaw_joint" forcerange="-4.8 4.8" inheritrange="1" />
    <position class="mjcf" name="neck_yaw_joint" joint="neck_yaw_joint" forcerange="-4.8 4.8" inheritrange="1" />
    <position class="mjcf" name="neck_roll_joint" joint="neck_roll_joint" forcerange="-4.8 4.8" inheritrange="1" />
    <position class="mjcf" name="neck_pitch_joint" joint="neck_pitch_joint" forcerange="-4.8 4.8" inheritrange="1" />
    <position name="left_finger1_joint1_actuator" joint="left_finger1_joint1" kp="0.5" ctrlrange="0.0583 1.5941" forcerange="-0.4452 0.4452" />
    <position name="left_finger1_joint2_actuator" joint="left_finger1_joint2" kp="0.5" ctrlrange="-0.1199 0.9335" forcerange="-0.4259 0.4259" />
    <position name="left_finger1_joint3_actuator" joint="left_finger1_joint3" kp="0.5" ctrlrange="-0.4646 1.5639" forcerange="-0.1888 0.1888" />
    <position name="left_finger1_joint4_actuator" joint="left_finger1_joint4" kp="0.5" ctrlrange="-0.457 1.5684" forcerange="-0.1468 0.1468" />
    <position name="left_finger2_joint1_actuator" joint="left_finger2_joint1" kp="0.5" ctrlrange="-0.156 1.5619" forcerange="-0.6188 0.6188" />
    <position name="left_finger2_joint2_actuator" joint="left_finger2_joint2" kp="0.5" ctrlrange="-0.4095 0.2921" forcerange="-0.1822 0.1822" />
    <position name="left_finger2_joint3_actuator" joint="left_finger2_joint3" kp="0.5" ctrlrange="-0.4839 1.5466" forcerange="-0.2251 0.2251" />
    <position name="left_finger2_joint4_actuator" joint="left_finger2_joint4" kp="0.5" ctrlrange="-0.4723 1.5754" forcerange="-0.217 0.217" />
    <position name="left_finger3_joint1_actuator" joint="left_finger3_joint1" kp="0.5" ctrlrange="-0.1569 1.5536" forcerange="-0.6494 0.6494" />
    <position name="left_finger3_joint2_actuator" joint="left_finger3_joint2" kp="0.5" ctrlrange="-0.3977 0.3115" forcerange="-0.1827 0.1827" />
    <position name="left_finger3_joint3_actuator" joint="left_finger3_joint3" kp="0.5" ctrlrange="-0.4847 1.5411" forcerange="-0.2078 0.2078" />
    <position name="left_finger3_joint4_actuator" joint="left_finger3_joint4" kp="0.5" ctrlrange="-0.4671 1.5788" forcerange="-0.2018 0.2018" />
    <position name="left_finger4_joint1_actuator" joint="left_finger4_joint1" kp="0.5" ctrlrange="-0.1507 1.5636" forcerange="-0.6389 0.6389" />
    <position name="left_finger4_joint2_actuator" joint="left_finger4_joint2" kp="0.5" ctrlrange="-0.4101 0.3014" forcerange="-0.1832 0.1832" />
    <position name="left_finger4_joint3_actuator" joint="left_finger4_joint3" kp="0.5" ctrlrange="-0.4747 1.5526" forcerange="-0.2249 0.2249" />
    <position name="left_finger4_joint4_actuator" joint="left_finger4_joint4" kp="0.5" ctrlrange="-0.4729 1.5718" forcerange="-0.2044 0.2044" />
    <position name="left_finger5_joint1_actuator" joint="left_finger5_joint1" kp="0.5" ctrlrange="-0.1578 1.5632" forcerange="-0.6441 0.6441" />
    <position name="left_finger5_joint2_actuator" joint="left_finger5_joint2" kp="0.5" ctrlrange="-0.4103 0.2949" forcerange="-0.1798 0.1798" />
    <position name="left_finger5_joint3_actuator" joint="left_finger5_joint3" kp="0.5" ctrlrange="-0.4733 1.556" forcerange="-0.2384 0.2384" />
    <position name="left_finger5_joint4_actuator" joint="left_finger5_joint4" kp="0.5" ctrlrange="-0.4662 1.576" forcerange="-0.1866 0.1866" />
    <position name="right_finger1_joint1_actuator" joint="right_finger1_joint1" kp="0.5" ctrlrange="0.0368 1.6125" forcerange="-0.4452 0.4452" />
    <position name="right_finger1_joint2_actuator" joint="right_finger1_joint2" kp="0.5" ctrlrange="-0.1576 0.9312" forcerange="-0.4259 0.4259" />
    <position name="right_finger1_joint3_actuator" joint="right_finger1_joint3" kp="0.5" ctrlrange="-0.4638 1.5607" forcerange="-0.1888 0.1888" />
    <position name="right_finger1_joint4_actuator" joint="right_finger1_joint4" kp="0.5" ctrlrange="-0.4829 1.5451" forcerange="-0.1468 0.1468" />
    <position name="right_finger2_joint1_actuator" joint="right_finger2_joint1" kp="0.5" ctrlrange="-0.1611 1.5588" forcerange="-0.6188 0.6188" />
    <position name="right_finger2_joint2_actuator" joint="right_finger2_joint2" kp="0.5" ctrlrange="-0.4044 0.3054" forcerange="-0.1822 0.1822" />
    <position name="right_finger2_joint3_actuator" joint="right_finger2_joint3" kp="0.5" ctrlrange="-0.4714 1.5504" forcerange="-0.2251 0.2251" />
    <position name="right_finger2_joint4_actuator" joint="right_finger2_joint4" kp="0.5" ctrlrange="-0.4644 1.5753" forcerange="-0.217 0.217" />
    <position name="right_finger3_joint1_actuator" joint="right_finger3_joint1" kp="0.5" ctrlrange="-0.1719 1.5496" forcerange="-0.6494 0.6494" />
    <position name="right_finger3_joint2_actuator" joint="right_finger3_joint2" kp="0.5" ctrlrange="-0.4014 0.2996" forcerange="-0.1827 0.1827" />
    <position name="right_finger3_joint3_actuator" joint="right_finger3_joint3" kp="0.5" ctrlrange="-0.4632 1.5613" forcerange="-0.2078 0.2078" />
    <position name="right_finger3_joint4_actuator" joint="right_finger3_joint4" kp="0.5" ctrlrange="-0.4697 1.5702" forcerange="-0.2018 0.2018" />
    <position name="right_finger4_joint1_actuator" joint="right_finger4_joint1" kp="0.5" ctrlrange="-0.1601 1.5534" forcerange="-0.6389 0.6389" />
    <position name="right_finger4_joint2_actuator" joint="right_finger4_joint2" kp="0.5" ctrlrange="-0.4134 0.3161" forcerange="-0.1832 0.1832" />
    <position name="right_finger4_joint3_actuator" joint="right_finger4_joint3" kp="0.5" ctrlrange="-0.4782 1.5448" forcerange="-0.2249 0.2249" />
    <position name="right_finger4_joint4_actuator" joint="right_finger4_joint4" kp="0.5" ctrlrange="-0.4825 1.555" forcerange="-0.2044 0.2044" />
    <position name="right_finger5_joint1_actuator" joint="right_finger5_joint1" kp="0.5" ctrlrange="-0.1674 1.5539" forcerange="-0.6441 0.6441" />
    <position name="right_finger5_joint2_actuator" joint="right_finger5_joint2" kp="0.5" ctrlrange="-0.4203 0.2931" forcerange="-0.1798 0.1798" />
    <position name="right_finger5_joint3_actuator" joint="right_finger5_joint3" kp="0.5" ctrlrange="-0.4804 1.542" forcerange="-0.2384 0.2384" />
    <position name="right_finger5_joint4_actuator" joint="right_finger5_joint4" kp="0.5" ctrlrange="-0.4705 1.5709" forcerange="-0.1866 0.1866" />
  </actuator>
  <sensor>
    <actuatorfrc name="u_waist_yaw_joint" actuator="waist_yaw_joint" />
    <actuatorfrc name="u_waist_left_joint" actuator="waist_left_joint" />
    <actuatorfrc name="u_waist_right_joint" actuator="waist_right_joint" />
    <actuatorfrc name="u_left_shoulder_pitch_joint" actuator="left_shoulder_pitch_joint" />
    <actuatorfrc name="u_left_shoulder_roll_joint" actuator="left_shoulder_roll_joint" />
    <actuatorfrc name="u_left_shoulder_yaw_joint" actuator="left_shoulder_yaw_joint" />
    <actuatorfrc name="u_left_elbow_pitch_joint" actuator="left_elbow_pitch_joint" />
    <actuatorfrc name="u_left_wrist_roll_joint" actuator="left_wrist_roll_joint" />
    <actuatorfrc name="u_left_wrist_pitch_joint" actuator="left_wrist_pitch_joint" />
    <actuatorfrc name="u_left_wrist_yaw_joint" actuator="left_wrist_yaw_joint" />
    <actuatorfrc name="u_right_shoulder_pitch_joint" actuator="right_shoulder_pitch_joint" />
    <actuatorfrc name="u_right_shoulder_roll_joint" actuator="right_shoulder_roll_joint" />
    <actuatorfrc name="u_right_shoulder_yaw_joint" actuator="right_shoulder_yaw_joint" />
    <actuatorfrc name="u_right_elbow_pitch_joint" actuator="right_elbow_pitch_joint" />
    <actuatorfrc name="u_right_wrist_roll_joint" actuator="right_wrist_roll_joint" />
    <actuatorfrc name="u_right_wrist_pitch_joint" actuator="right_wrist_pitch_joint" />
    <actuatorfrc name="u_right_wrist_yaw_joint" actuator="right_wrist_yaw_joint" />
    <actuatorfrc name="u_neck_yaw_joint" actuator="neck_yaw_joint" />
    <actuatorfrc name="u_neck_roll_joint" actuator="neck_roll_joint" />
    <actuatorfrc name="u_neck_pitch_joint" actuator="neck_pitch_joint" />
  </sensor>
  <contact>
    <exclude body1="chest_link" body2="waist_yaw_link" />
    <exclude body1="waist_yaw_link" body2="waist_left_passive_link" />
    <exclude body1="waist_yaw_link" body2="waist_right_passive_link" />
    <exclude body1="neck_pitch_link" body2="neck_yaw_link" />
    <exclude body1="left_wrist_roll_link" body2="left_wrist_yaw_link" />
    <exclude body1="right_wrist_roll_link" body2="right_wrist_yaw_link" />
  </contact>
  <equality>
    <connect site1="closing_waist_left_passive2_joint_1" site2="closing_waist_left_passive2_joint_2" solref="0.002 1" solimp="0.9 0.9 0.01" />
    <connect site1="closing_waist_right_passive2_joint_1" site2="closing_waist_right_passive2_joint_2" solref="0.002 1" solimp="0.9 0.9 0.01" />
  </equality>
</mujoco>